Workbook

Sheet 卫星表
A1: 序号 | B1: 卫星名称 | C1: 卫星代号 | D1: 轨道位置 | E1: 状态 | F1: 覆盖范围 | G1: 转发器数量 | H1: 信标（MHz） | I1: 极化方式 | J1: 发射时间 | K1: 设计寿命 | L1: 卫星归属 | M1: 制造商 | N1: 卫星平台 | O1: 姿态稳定 | P1: 位保精度 | Q1: 备注
A2: 1 | B2: 中星6D卫星 | C2: CS6D | D2: 125°E | E2: 在轨运营 | F2: C频段：中国（含港澳、台湾）、南亚、西亚、东亚、中亚、东南亚、澳洲和南太平洋岛国 Ku频段：中国大陆地区及周边沿海、菲律宾和马来西亚 | G2: C频段25个转发器 Ku频段25个转发器 | H2: C频段： 下行水平信标：4198.5（H） 下行垂直信标：4197（V） Ku频段： 下行水平信标：12251（H） 下行垂直信标：12250.5（V） | I2: 线极化 | J2: 44666 | K2: 15年 | L2: 自有 | M2: 中国空间技术研究院 | N2: 东四增强型(DFH-4E) | O2: 三轴稳定 | P2: ±0.05°（E-W & N-S）
A3: 2 | B3: 中星6E卫星 | C3: CS6E | D3: 115.5°E | E3: 在轨运营 | F3: C波段：中国领土领水、东南亚和其它亚洲和大洋洲卫星可见陆地地区 | G3: C频段23个转发器 前向Ku频段10个转发器 返向Ka频段2个转发器 | H3: C频段： 下行水平信标：3702（H） 下行垂直信标：4198（V） Ku频段： 11700MHz（V） 12749MHz (V) Ka频段： 18700MHz（LHCP） | I3: 线极化 | J3: 45239 | K3: 14.2年 | L3: 自有 | M3: 中国空间技术研究院 | N3: 东四增强型(DFH-4E) | O3: 三轴稳定 | P3: ±0.05°（E-W & N-S）
A4: 3 | B4: 中星9B卫星 | C4: CS9B | D4: 101.4°E | E4: 在轨运营 | F4: 中国及周边海域 | G4: Ku频段25个转发器 | H4: 左旋信标：11700（LHCP） 右旋信标：12200（RHCP） | I4: 圆极化 | J4: 44448 | K4: 15年 | L4: 自有 | M4: 中国空间技术研究院 | N4: 东四增强型(DFH-4E) | O4: 三轴稳定 | P4: ±0.05°（E-W & N-S）
A5: 4 | B5: 中星9C卫星 | C5: CS9C | D5: 92.2°E | E5: 在轨运营 | F5: KuBSS频段：中国及周边海域 标准Ku频段：北京 规划Ku频段：中国西部地区 KaBSS频段：北京 | G5: KuBSS频段24个转发器 标准Ku频段5个转发器 规划Ku频段5个转发器 KaBSS频段1个转发器 | H5: 左旋信标：12199（LHCP） 右旋信标：11700（RHCP） | I5: 圆极化 | J5: 45828 | K5: 15年 | L5: 自有 | M5: 中国空间技术研究院 | N5: 东四增强型(DFH-4E) | O5: 三轴稳定 | P5: ±0.05°（E-W & N-S）
A6: 5 | B6: 中星10R卫星 | C6: CS10R | D6: 110.5°E | E6: 在轨运营 | F6: 中国陆地及领海、印尼、马来西亚、南亚、中东及阿拉伯海 | G6: Ku频段35个转发器 | H6: 12748 MHz（V）、 12745MHz（H） 11450.5 MHz（V）、 11452.5 MHz（H） | I6: 线极化 | J6: 45710 | K6: 15年 | L6: 自有 | M6: 中国空间技术研究院 | N6: 东四增强型(DFH-4E) | O6: 三轴稳定 | P6: ±0.05°（E-W & N-S）
A7: 6 | B7: 中星11号卫星（98E卫星） | C7: CS11 | D7: 98°E | E7: 在轨运营 | F7: C频段：区域波束 Ku频段：海洋波束、印尼波束、南亚波束（已永久关闭） | G7: C频段26个转发器 Ku频段19个转发器 | H7: C频段： 4198.3MHz(V) 4199.9MHz(H) Ku频段： 12737.5MHz（V） 11451MHz(V) 11453MHz(H) | I7: 线极化 | J7: 41396 | K7: 14年 | L7: 自有 | M7: 中国空间技术研究院 | N7: 东方红四号（DFH-4) | O7: 三轴稳定 | P7: ±0.05°（E-W & N-S）
A8: 7 | B8: 中星12号卫星（中卫2号） | C8: CS12 | D8: 87.5°E | E8: 在轨运营 | F8: C频段：全球波束 Ku频段：中国波束 Ku频段：中东非波束 Ku频段：可移动点波束 | G8: C频段24个转发器 Ku频段23个转发器 | H8: C频段： 3701.5MHz(V) 4199.3MHz(H) Ku频段： 11699.8MHz(LHCP) 12251MHz (RHCP) | I8: 线极化 | J8: 41240 | K8: 15年 | L8: 自有 | M8: 法国泰雷兹阿莱尼亚宇航公司 | N8: SB4000C2 | O8: 三轴稳定 | P8: ±0.05°（E-W & N-S）
A9: 8 | B9: 中星15号卫星 | C9: CS15 | D9: 51.5°E | E9: 在轨运营 | F9: 非规划Ku频段：非洲波束 规划Ku频段：欧洲波束 C频段：全球波束 C频段：非洲波束 C频段：东部波束 | G9: C频段20个转发器，归属中国卫通7个 Ku频段18个转发器，归属中国卫通1个 | H9: C频段： 4194MHz(RHCP) 4195.6MHz(LHCP) Ku频段： 11194MHz(V)非洲波束 11197MHz(H) 非洲波束 11445Mhz(H)欧洲波束 | I9: 圆极化（C） 线极化（Ku） | J9: 42386 | K9: 15年 | L9: 自有 | M9: 中国空间技术研究院 | N9: 东方红四号(DFH-4) | O9: 三轴稳定 | P9: ±0.05°（E-W & N-S）
A10: 9 | B10: 中星19号卫星 | C10: CS19 | D10: 163°E | E10: 在轨运营 | F10: 中国东部国土、东南亚以及包含北美航线在内的大部分太平洋区域 | G10: C频段2个 Ku频段13个 前向Ka频段14个 返向Ka频段2个 | H10: C频段： 4199.8MHz(L) Ku频段： 11691MHz（H） 11695MHz（V） Ka频段： 19700MHz(RHCP) | I10: 线极化 | J10: 44870 | K10: 12.5年 | L10: 自有 | M10: 中国空间技术研究院 | N10: 东四增强型(DFH-4E) | O10: 三轴稳定 | P10: ±0.05°（E-W & N-S）
A11: 10 | B11: 中星26号卫星 | C11: CS26 | D11: 125°E | E11: 在轨运营 | F11: 中国全境及周边水域、俄罗斯部分地区、东南亚、蒙古、日本、印度尼西亚、印度、印度洋等地区 | G11: 前向Ka频段36个 返向Ka频段 14个 | H11: 19130MHz(RHCP)\(LHCP) | I11: 圆极化 | J11: 44980 | K11: 15年 | L11: 自有 | M11: 中国空间技术研究院 | N11: 东四增强型(DFH-4E) | O11: 三轴稳定 | P11: ±0.05°（E-W & N-S）
A12: 11 | B12: 亚太5C卫星 | C12: APT-5C | D12: 138°E | E12: 在轨运营 | F12: AP波束： 中国、东南亚、澳大利亚及南太平洋岛国、夏威夷 6个区域波束： CHN波束：中国 MNG波束：蒙古 IC波束：中南半岛 IMR波束：印度尼西亚及马来西亚 ANZ波束：南太平洋区域 NP波束：北太平洋区域 | G12: C波段34个转发器 Ku波段20个转发器 | I12: 线极化 | J12: 43353 | K12: 15年 | L12: 代理 | M12: 劳拉空间系统公司 | N12: SSL 1300 | O12: 三轴稳定 | P12: ±0.05°（E-W & N-S）
A13: 12 | B13: 亚太6C卫星 | C13: APT-6C | D13: 134°E | E13: 在轨运营 | F13: C波段： AP波束：中国、东南亚、澳大利亚及南太平洋岛国 Ku波段： CHN波束：中国 MNG波束：蒙古 IC波束：中南半岛 Ka波段： Ka北波束：北京/上海、渤海、黄海、东海 Ka南波束：广州/香港、部分南海 | G13: C波段32个转发器 Ku波段20个转发器 Ka波段1个转发器 | I13: 线极化（C） 线极化（Ku） 圆极化（Ka） | J13: 43224 | K13: 15年 | L13: 代理 | M13: 中国空间技术研究院 | N13: 东方红四号（DFH-4) | O13: 三轴稳定 | P13: ±0.05°（E-W & N-S）
A14: 13 | B14: 亚太6D卫星 | C14: APT-6D | D14: 134°E | E14: 在轨运营 | F14: 所在轨位对地球可视范围的全部覆盖，以亚太区域为重点，包括中国、周边地区、东南亚的覆盖 | I14: 线极化 | J14: 44021 | K14: 15年 | L14: 代理 | M14: 中国空间技术研究院 | N14: 东四增强型(DFH-4E) | O14: 三轴稳定 | P14: ±0.05°（E-W & N-S）
A15: 14 | B15: 亚太6E卫星 | C15: APT-6E | D15: 134°E | E15: 在轨运营 | F15: Ku频段：印尼全境覆盖 Ka频段：东南亚 | J15: 44939 | K15: 15年 | L15: 代理 | M15: 中国空间技术研究院 | N15: 东方红三号增强型(DFH-3E) | O15: 三轴稳定 | P15: ±0.05°（E-W & N-S）
A16: 15 | B16: 亚太7号卫星 | C16: APT-7 | D16: 76.5°E | E16: 在轨运营 | F16: C波段： 亚洲、澳洲、非洲、欧洲大部及太平洋、印度洋可视范围内的主要岛屿和海域 Ku波段： CHN波束：中国及周边部分地区 MENA波束：中东、北非、中亚及部分欧洲地区 AFR波束：非洲大部 SSB波束：可指向可视区域内的任意一点 以上4个波束间可实现上、下行互相交链 | G16: C波段28个转发器 Ku波段28个转发器 | I16: 线极化 | J16: 40999 | K16: 15年 | L16: 代理 | M16: 法国泰雷兹阿莱尼亚宇航公司 | N16: SB4000C2 | O16: 三轴稳定 | P16: ±0.05°（E-W & N-S）
A17: 16 | B17: 亚太9号卫星 | C17: APT-9 | D17: 142°E | E17: 在轨运营 | F17: C波段： SEA波束： 印尼、马来西亚、巴新及周边地区 AP波束： 亚太地区 Ku波段： 西波束+ 北波束+ 南波束：形成东印度洋到西太平洋的完整覆盖 可移动波束：可指向可视区域内的任意一点 以上4个波束间可实现上、下行互相交链 | G17: C波段32个转发器 Ku波段14个转发器 | I17: 线极化 | J17: 42294 | K17: 15年 | L17: 代理 | M17: 中国空间技术研究院 | N17: 东方红四号（DFH-4) | O17: 三轴稳定 | P17: ±0.05°（E-W & N-S）
A18: 17 | B18: 中星6C卫星 | C18: CS6C | D18: 130°E | E18: 在轨运营 | F18: 中国及周边地区、澳大利亚及南太岛国等国家和地区 | G18: C频段25个转发器 | H18: C频段： 下行水平信标：3676.5（H） 下行垂直信标：3642（V） | I18: 线极化 | J18: 43534 | K18: 15年 | L18: 自有 | M18: 中国空间技术研究院 | N18: 东方红四号（DFH-4) | O18: 三轴稳定 | P18: ±0.05°（E-W & N-S）
A19: 18 | B19: 中星16号卫星 | C19: CS16 | D19: 110.5°E | E19: 在轨运营 | F19: 中国及近海区域 | G19: 前向Ka频段10个转发器 返向Ka频段6个转发器 | H19: 18508.8MHz(RHCP)\(LHCP) | I19: 圆极化 | J19: 42837 | K19: 15年 | L19: 自有 | M19: 中国空间技术研究院 | N19: 东方红三号B卫星平台(DFH-3B) | O19: 三轴稳定 | P19: ±0.05°（E-W & N-S）
A20: 20 | B20: 中星9号卫星 | C20: CS9 | D20: 92.2°E | E20: 停止服务 | F20: 中国及周边地区 | G20: 22个DBS频段转发器 | I20: 圆极化 | J20: 39608 | K20: 15年 | L20: 自有 | M20: 法国泰雷兹阿莱尼亚宇航公司 | N20: SB4000 | O20: 三轴稳定 | P20: ±0.05°（E-W & N-S）
A21: 21 | B21: 中星10号卫星（鑫诺5号） | C21: CS10 | D21: 110.5°E | E21: 停止服务 | F21: 中国及周边地区 | G21: C频段30个转发器 Ku频段16个转发器 | I21: 线极化 | J21: 40715 | K21: 13.5年 | L21: 自有 | M21: 中国空间技术研究院 | N21: 东方红四号（DFH-4) | O21: 三轴稳定 | P21: ±0.05°（E-W & N-S）
A22: 19 | B22: 中星6B卫星 | C22: CS6B | D22: 115.5°E | E22: 离轨 | F22: 中国、蒙古、朝鲜半岛、日本、俄罗斯亚洲部分、南亚、东南亚、中亚、西亚、澳大利亚、新西兰 | G22: C频段38个转发器 | I22: 线极化 | J22: 39268 | K22: 15年 | L22: 自有 | M22: 法国阿尔卡特阿莱尼亚宇航公司 | N22: SB4000 | O22: 三轴稳定 | P22: ±0.05°（E-W & N-S）
A23: 22 | B23: 亚太5号卫星 | C23: APT-5 | D23: 138°E | E23: 离轨 | F23: 中国及周边地区 | I23: 线极化 | L23: 代理 | O23: 三轴稳定 | P23: ±0.05°（E-W & N-S）
A24: 23 | B24: 亚太6号卫星 | C24: APT-6 | D24: 134°E | E24: 离轨 | F24: 中国及周边地区 | I24: 线极化 | L24: 代理 | O24: 三轴稳定 | P24: ±0.05°（E-W & N-S）
A25: 24 | B25: 中星6A卫星（鑫诺6号） | C25: CS6A | E25: 离轨
A26: 25 | B26: 中星9A卫星（鑫诺4号） | C26: CS9A | E26: 离轨
A27: 26 | B27: 中星27号卫星 | C27: CS27 | E27: 在建

Sheet 通道基本信息
A1: ID | B1: 通道组代号 | C1: 通道组序号 | D1: 卫星 | E1: 天线 | F1: 波束代号 | G1: 收发(R/T) | H1: 参考序号 | I1: 极化 | J1: 频率 | K1: 通道数
A2: 1 | B2: =D2&"-"&C2&"-"&K2 -> CS10R-R001-9 | C2: =G2&TEXT(H2,"000") -> R001 | D2: CS10R | E2: 国土波束 | F2: C | G2: R | H2: 1 | I2: H | J2: Ku | K2: 9
A3: 2 | B3: =D3&"-"&C3&"-"&K3 -> CS10R-R002-4 | C3: =G3&TEXT(H3,"000") -> R002 | D3: CS10R | E3: 国土波束 | F3: C | G3: R | H3: 2 | I3: H | J3: EKu | K3: 4
A4: 3 | B4: =D4&"-"&C4&"-"&K4 -> CS10R-R003-8 | C4: =G4&TEXT(H4,"000") -> R003 | D4: CS10R | E4: 国土波束 | F4: C | G4: R | H4: 3 | I4: V | J4: Ku | K4: 8
A5: 4 | B5: =D5&"-"&C5&"-"&K5 -> CS10R-R004-4 | C5: =G5&TEXT(H5,"000") -> R004 | D5: CS10R | E5: 国土波束 | F5: C | G5: R | H5: 4 | I5: V | J5: EKu | K5: 4
A6: 5 | B6: =D6&"-"&C6&"-"&K6 -> CS10R-R005-4 | C6: =G6&TEXT(H6,"000") -> R005 | D6: CS10R | E6: 南海波束 | F6: S | G6: R | H6: 5 | I6: V | J6: Ku | K6: 4
A7: 6 | B7: =D7&"-"&C7&"-"&K7 -> CS10R-R006-4 | C7: =G7&TEXT(H7,"000") -> R006 | D7: CS10R | E7: 西部波束 | F7: W | G7: R | H7: 6 | I7: V | J7: EKu | K7: 4
A8: 7 | B8: =D8&"-"&C8&"-"&K8 -> CS10R-R007-4 | C8: =G8&TEXT(H8,"000") -> R007 | D8: CS10R | E8: 印尼波束 | F8: I | G8: R | H8: 7 | I8: H | J8: Ku | K8: 4
A9: 8 | B9: =D9&"-"&C9&"-"&K9 -> CS10R-R008-4 | C9: =G9&TEXT(H9,"000") -> R008 | D9: CS10R | E9: 印尼波束 | F9: I | G9: R | H9: 8 | I9: H | J9: EKu | K9: 4
A10: 9 | B10: =D10&"-"&C10&"-"&K10 -> CS10R-R009-4 | C10: =G10&TEXT(H10,"000") -> R009 | D10: CS10R | E10: 印尼波束 | F10: I | G10: R | H10: 9 | I10: V | J10: EKu | K10: 4
A11: 10 | B11: =D11&"-"&C11&"-"&K11 -> CS10R-R010-3 | C11: =G11&TEXT(H11,"000") -> R010 | D11: CS10R | E11: 西部波束 | F11: W | G11: R | H11: 10 | I11: V | J11: Ku | K11: 3
A12: 11 | B12: =D12&"-"&C12&"-"&K12 -> CS10R-R011-3 | C12: =G12&TEXT(H12,"000") -> R011 | D12: CS10R | E12: 东部波束 | F12: E | G12: R | H12: 11 | I12: V | J12: EKu | K12: 3
A13: 12 | B13: =D13&"-"&C13&"-"&K13 -> CS10R-T001-9 | C13: =G13&TEXT(H13,"000") -> T001 | D13: CS10R | E13: 国土波束 | F13: C | G13: T | H13: 1 | I13: V | J13: Ku | K13: 9
... A432: 431 | B432: =D432&"-"&C432&"-"&K432 -> CS26-T122-4 | C432: =G432&TEXT(H432,"000") -> T122 | D432: CS26 | E432: 银川馈电波束（备份成都） | F432: B | G432: T | H432: 122 | I432: R | J432: Ka | K432: 4
A433: 432 | B433: =D433&"-"&C433&"-"&K433 -> CS6E-R001-1 | C433: =G433&TEXT(H433,"000") -> R001 | D433: CS6E | E433: 1 | F433: S01 | G433: R | H433: 1 | I433: H | J433: Ku | K433: 1 | L433: 模拟
A434: 433 | B434: =D434&"-"&C434&"-"&K434 -> CS6E-R002-24 | C434: =G434&TEXT(H434,"000") -> R002 | D434: CS6E | E434: 1 | F434: S01 | G434: R | H434: 2 | I434: H | J434: Ku | K434: 24 | L434: 数字
A435: 434 | B435: =D435&"-"&C435&"-"&K435 -> CS6E-R003-1 | C435: =G435&TEXT(H435,"000") -> R003 | D435: CS6E | E435: 2 | F435: S02 | G435: R | H435: 3 | I435: H | J435: Ku | K435: 1 | L435: 模拟
A436: 435 | B436: =D436&"-"&C436&"-"&K436 -> CS6E-R004-24 | C436: =G436&TEXT(H436,"000") -> R004 | D436: CS6E | E436: 2 | F436: S02 | G436: R | H436: 4 | I436: H | J436: Ku | K436: 24 | L436: 数字
A437: 436 | B437: =D437&"-"&C437&"-"&K437 -> CS6E-R005-1 | C437: =G437&TEXT(H437,"000") -> R005 | D437: CS6E | E437: 3 | F437: S03 | G437: R | H437: 5 | I437: H | J437: Ku | K437: 1 | L437: 模拟
A438: 437 | B438: =D438&"-"&C438&"-"&K438 -> CS6E-R006-28 | C438: =G438&TEXT(H438,"000") -> R006 | D438: CS6E | E438: 3 | F438: S03 | G438: R | H438: 6 | I438: H | J438: Ku | K438: 28 | L438: 数字
A439: 438 | B439: =D439&"-"&C439&"-"&K439 -> CS6E-R007-1 | C439: =G439&TEXT(H439,"000") -> R007 | D439: CS6E | E439: 4 | F439: S04 | G439: R | H439: 7 | I439: H | J439: Ku | K439: 1 | L439: 模拟
A440: 439 | B440: =D440&"-"&C440&"-"&K440 -> CS6E-R008-24 | C440: =G440&TEXT(H440,"000") -> R008 | D440: CS6E | E440: 4 | F440: S04 | G440: R | H440: 8 | I440: H | J440: Ku | K440: 24 | L440: 数字
A441: 440 | B441: =D441&"-"&C441&"-"&K441 -> CS6E-R009-1 | C441: =G441&TEXT(H441,"000") -> R009 | D441: CS6E | E441: 5 | F441: S05 | G441: R | H441: 9 | I441: V | J441: Ku | K441: 1 | L441: 模拟
A442: 441 | B442: =D442&"-"&C442&"-"&K442 -> CS6E-R010-180 | C442: =G442&TEXT(H442,"000") -> R010 | D442: CS6E | E442: 5 | F442: S05 | G442: R | H442: 10 | I442: V | J442: Ku | K442: 180 | L442: 数字
A443: 442 | B443: =D443&"-"&C443&"-"&K443 -> CS6E-R011-1 | C443: =G443&TEXT(H443,"000") -> R011 | D443: CS6E | E443: 6 | F443: S06 | G443: R | H443: 11 | I443: H | J443: EKu | K443: 1 | L443: 模拟
A444: 443 | B444: =D444&"-"&C444&"-"&K444 -> CS6E-R012-28 | C444: =G444&TEXT(H444,"000") -> R012 | D444: CS6E | E444: 6 | F444: S06 | G444: R | H444: 12 | I444: H | J444: EKu | K444: 28 | L444: 数字
... A467: 466 | B467: =D467&"-"&C467&"-"&K467 -> CS6E-R035-40 | C467: =G467&TEXT(H467,"000") -> R035 | D467: CS6E | E467: 24 | F467: S24 | G467: R | H467: 35 | I467: H | J467: Ku | K467: 40 | L467: 数字
A468: 467 | B468: =D468&"-"&C468&"-"&K468 -> CS6E-R036-12 | C468: =G468&TEXT(H468,"000") -> R036 | D468: CS6E | E468: 馈电波束-怀来 | F468: K-HL | G468: R | H468: 36 | I468: R | J468: Ka | K468: 12 | L468: 模拟
A469: 468 | B469: =D469&"-"&C469&"-"&K469 -> CS6E-R037-224 | C469: =G469&TEXT(H469,"000") -> R037 | D469: CS6E | E469: 馈电波束-怀来 | F469: K-HL | G469: R | H469: 37 | I469: R | J469: Ka | K469: 224 | L469: 数字
A470: 469 | B470: =D470&"-"&C470&"-"&K470 -> CS6E-R038-12 | C470: =G470&TEXT(H470,"000") -> R038 | D470: CS6E | E470: 馈电波束-怀来 | F470: K-HL | G470: R | H470: 38 | I470: L | J470: Ka | K470: 12 | L470: 模拟
A471: 470 | B471: =D471&"-"&C471&"-"&K471 -> CS6E-R039-340 | C471: =G471&TEXT(H471,"000") -> R039 | D471: CS6E | E471: 馈电波束-怀来 | F471: K-HL | G471: R | H471: 39 | I471: L | J471: Ka | K471: 340 | L471: 数字
A472: 471 | B472: =D472&"-"&C472&"-"&K472 -> CS6E-R040-1 | C472: =G472&TEXT(H472,"000") -> R040 | D472: CS6E | E472: 信令-Ku | F472: XL | G472: R | H472: 40 | I472: H | J472: Ku | K472: 1 | L472: 模拟
A473: 472 | B473: =D473&"-"&C473&"-"&K473 -> CS6E-R041-1 | C473: =G473&TEXT(H473,"000") -> R041 | D473: CS6E | E473: 信令-EKu | F473: XL | G473: R | H473: 41 | I473: H | J473: EKu | K473: 1 | L473: 模拟
A474: 473 | B474: =D474&"-"&C474&"-"&K474 -> CS6E-T001-1 | C474: =G474&TEXT(H474,"000") -> T001 | D474: CS6E | E474: 1 | F474: S01 | G474: T | H474: 1 | I474: V | J474: Ku | K474: 1 | L474: 模拟
A475: 474 | B475: =D475&"-"&C475&"-"&K475 -> CS6E-T002-24 | C475: =G475&TEXT(H475,"000") -> T002 | D475: CS6E | E475: 1 | F475: S01 | G475: T | H475: 2 | I475: V | J475: Ku | K475: 24 | L475: 数字
A476: 475 | B476: =D476&"-"&C476&"-"&K476 -> CS6E-T003-1 | C476: =G476&TEXT(H476,"000") -> T003 | D476: CS6E | E476: 2 | F476: S02 | G476: T | H476: 3 | I476: V | J476: Ku | K476: 1 | L476: 模拟
A477: 476 | B477: =D477&"-"&C477&"-"&K477 -> CS6E-T004-24 | C477: =G477&TEXT(H477,"000") -> T004 | D477: CS6E | E477: 2 | F477: S02 | G477: T | H477: 4 | I477: V | J477: Ku | K477: 24 | L477: 数字
A478: 477 | B478: =D478&"-"&C478&"-"&K478 -> CS6E-T005-1 | C478: =G478&TEXT(H478,"000") -> T005 | D478: CS6E | E478: 3 | F478: S03 | G478: T | H478: 5 | I478: V | J478: Ku | K478: 1 | L478: 模拟
A479: 478 | B479: =D479&"-"&C479&"-"&K479 -> CS6E-T006-28 | C479: =G479&TEXT(H479,"000") -> T006 | D479: CS6E | E479: 3 | F479: S03 | G479: T | H479: 6 | I479: V | J479: Ku | K479: 28 | L479: 数字
A480: 479 | B480: =D480&"-"&C480&"-"&K480 -> CS6E-T007-1 | C480: =G480&TEXT(H480,"000") -> T007 | D480: CS6E | E480: 4 | F480: S04 | G480: T | H480: 7 | I480: V | J480: Ku | K480: 1 | L480: 模拟
...

Sheet 通道清单
A1: ID | B1: 通道代号 | C1: 通道全称 | D1: 通道简称 | E1: 索引收发 | F1: 索引波束 | G1: 索引极化 | H1: 通道组代号 | I1: 参考序号 | J1: 通道带宽 | K1: 通道起频率 | L1: 通道止频率 | M1: 常用名-旧 | N1: 常用名 | O1: 索引“卫星”
A2: 1 | B2: =H2&"-"&I2 -> CS10R-R001-9-1 | C2: =O2&"-"&D2 -> CS10R-RC1A | D2: RC1A | E2: =VLOOKUP(H2,通道基本信息!B:K,6,0) -> R | F2: =VLOOKUP(H2,通道基本信息!B:K,5,0) -> C | G2: =VLOOKUP(H2,通道基本信息!B:K,8,0) -> H | H2: CS10R-R001-9 | I2: 1 | J2: 30 | K2: 14008 | L2: 14038 | M2: C1A | N2: C1A | O2: =VLOOKUP(H2,通道基本信息!B:L,3,FALSE) -> CS10R
A3: 2 | B3: =H3&"-"&I3 -> CS10R-R001-9-2 | C3: =O3&"-"&D3 -> CS10R-RC2A | D3: RC2A | E3: =VLOOKUP(H3,通道基本信息!B:K,6,0) -> R | F3: =VLOOKUP(H3,通道基本信息!B:K,5,0) -> C | G3: =VLOOKUP(H3,通道基本信息!B:K,8,0) -> H | H3: CS10R-R001-9 | I3: 2 | J3: 54 | K3: 14043 | L3: 14097 | M3: C2A | N3: C2A | O3: =VLOOKUP(H3,通道基本信息!B:L,3,FALSE) -> CS10R
A4: 3 | B4: =H4&"-"&I4 -> CS10R-R001-9-3 | C4: =O4&"-"&D4 -> CS10R-RC3A | D4: RC3A | E4: =VLOOKUP(H4,通道基本信息!B:K,6,0) -> R | F4: =VLOOKUP(H4,通道基本信息!B:K,5,0) -> C | G4: =VLOOKUP(H4,通道基本信息!B:K,8,0) -> H | H4: CS10R-R001-9 | I4: 3 | J4: 54 | K4: 14103 | L4: 14157 | M4: C3A | N4: C3A | O4: =VLOOKUP(H4,通道基本信息!B:L,3,FALSE) -> CS10R
A5: 4 | B5: =H5&"-"&I5 -> CS10R-R001-9-4 | C5: =O5&"-"&D5 -> CS10R-RC4A | D5: RC4A | E5: =VLOOKUP(H5,通道基本信息!B:K,6,0) -> R | F5: =VLOOKUP(H5,通道基本信息!B:K,5,0) -> C | G5: =VLOOKUP(H5,通道基本信息!B:K,8,0) -> H | H5: CS10R-R001-9 | I5: 4 | J5: 54 | K5: 14163 | L5: 14217 | M5: C4A | N5: C4A | O5: =VLOOKUP(H5,通道基本信息!B:L,3,FALSE) -> CS10R
A6: 5 | B6: =H6&"-"&I6 -> CS10R-R001-9-5 | C6: =O6&"-"&D6 -> CS10R-RC5A | D6: RC5A | E6: =VLOOKUP(H6,通道基本信息!B:K,6,0) -> R | F6: =VLOOKUP(H6,通道基本信息!B:K,5,0) -> C | G6: =VLOOKUP(H6,通道基本信息!B:K,8,0) -> H | H6: CS10R-R001-9 | I6: 5 | J6: 54 | K6: 14223 | L6: 14277 | M6: C5A | N6: C5A | O6: =VLOOKUP(H6,通道基本信息!B:L,3,FALSE) -> CS10R
A7: 6 | B7: =H7&"-"&I7 -> CS10R-R001-9-6 | C7: =O7&"-"&D7 -> CS10R-RC6A | D7: RC6A | E7: =VLOOKUP(H7,通道基本信息!B:K,6,0) -> R | F7: =VLOOKUP(H7,通道基本信息!B:K,5,0) -> C | G7: =VLOOKUP(H7,通道基本信息!B:K,8,0) -> H | H7: CS10R-R001-9 | I7: 6 | J7: 54 | K7: 14283 | L7: 14337 | M7: C6A | N7: C6A | O7: =VLOOKUP(H7,通道基本信息!B:L,3,FALSE) -> CS10R
A8: 7 | B8: =H8&"-"&I8 -> CS10R-R001-9-7 | C8: =O8&"-"&D8 -> CS10R-RC7A | D8: RC7A | E8: =VLOOKUP(H8,通道基本信息!B:K,6,0) -> R | F8: =VLOOKUP(H8,通道基本信息!B:K,5,0) -> C | G8: =VLOOKUP(H8,通道基本信息!B:K,8,0) -> H | H8: CS10R-R001-9 | I8: 7 | J8: 54 | K8: 14343 | L8: 14397 | M8: C7A | N8: C7A | O8: =VLOOKUP(H8,通道基本信息!B:L,3,FALSE) -> CS10R
A9: 8 | B9: =H9&"-"&I9 -> CS10R-R001-9-8 | C9: =O9&"-"&D9 -> CS10R-RC8A | D9: RC8A | E9: =VLOOKUP(H9,通道基本信息!B:K,6,0) -> R | F9: =VLOOKUP(H9,通道基本信息!B:K,5,0) -> C | G9: =VLOOKUP(H9,通道基本信息!B:K,8,0) -> H | H9: CS10R-R001-9 | I9: 8 | J9: 54 | K9: 14403 | L9: 14457 | M9: C8A | N9: C8A | O9: =VLOOKUP(H9,通道基本信息!B:L,3,FALSE) -> CS10R
A10: 9 | B10: =H10&"-"&I10 -> CS10R-R001-9-9 | C10: =O10&"-"&D10 -> CS10R-RC9A | D10: RC9A | E10: =VLOOKUP(H10,通道基本信息!B:K,6,0) -> R | F10: =VLOOKUP(H10,通道基本信息!B:K,5,0) -> C | G10: =VLOOKUP(H10,通道基本信息!B:K,8,0) -> H | H10: CS10R-R001-9 | I10: 9 | J10: 30 | K10: 14463 | L10: 14493 | M10: C9A | N10: C9A | O10: =VLOOKUP(H10,通道基本信息!B:L,3,FALSE) -> CS10R
A11: 10 | B11: =H11&"-"&I11 -> CS10R-R002-4-1 | C11: =O11&"-"&D11 -> CS10R-RC11A | D11: RC11A | E11: =VLOOKUP(H11,通道基本信息!B:K,6,0) -> R | F11: =VLOOKUP(H11,通道基本信息!B:K,5,0) -> C | G11: =VLOOKUP(H11,通道基本信息!B:K,8,0) -> H | H11: CS10R-R002-4 | I11: 1 | J11: 34 | K11: 13762 | L11: 13796 | M11: C11A | N11: C11A | O11: =VLOOKUP(H11,通道基本信息!B:L,3,FALSE) -> CS10R
A12: 11 | B12: =H12&"-"&I12 -> CS10R-R002-4-2 | C12: =O12&"-"&D12 -> CS10R-RC12A | D12: RC12A | E12: =VLOOKUP(H12,通道基本信息!B:K,6,0) -> R | F12: =VLOOKUP(H12,通道基本信息!B:K,5,0) -> C | G12: =VLOOKUP(H12,通道基本信息!B:K,8,0) -> H | H12: CS10R-R002-4 | I12: 2 | J12: 65 | K12: 13806 | L12: 13871 | M12: C12A | N12: C12A | O12: =VLOOKUP(H12,通道基本信息!B:L,3,FALSE) -> CS10R
A13: 12 | B13: =H13&"-"&I13 -> CS10R-R002-4-3 | C13: =O13&"-"&D13 -> CS10R-RC13A | D13: RC13A | E13: =VLOOKUP(H13,通道基本信息!B:K,6,0) -> R | F13: =VLOOKUP(H13,通道基本信息!B:K,5,0) -> C | G13: =VLOOKUP(H13,通道基本信息!B:K,8,0) -> H | H13: CS10R-R002-4 | I13: 3 | J13: 52 | K13: 13878 | L13: 13930 | M13: C13A | N13: C13A | O13: =VLOOKUP(H13,通道基本信息!B:L,3,FALSE) -> CS10R
... A307: 306 | B307: =H307&"-"&I307 -> CS15-R003-3-3 | C307: =O307&"-"&D307 -> CS15-RWC21L | D307: RWC21L | E307: =VLOOKUP(H307,通道基本信息!B:K,6,0) -> R | F307: =VLOOKUP(H307,通道基本信息!B:K,5,0) -> W | G307: =VLOOKUP(H307,通道基本信息!B:K,8,0) -> L | H307: CS15-R003-3 | I307: 3 | J307: 36 | K307: 6337 | L307: 6373 | M307: C21 | N307: WC21L | O307: =VLOOKUP(H307,通道基本信息!B:L,3,FALSE) -> CS15
A308: 307 | B308: =H308&"-"&I308 -> CS15-R004-4-1 | C308: =O308&"-"&D308 -> CS15-RFK1H | D308: RFK1H | E308: =VLOOKUP(H308,通道基本信息!B:K,6,0) -> R | F308: =VLOOKUP(H308,通道基本信息!B:K,5,0) -> F | G308: =VLOOKUP(H308,通道基本信息!B:K,8,0) -> H | H308: CS15-R004-4 | I308: 1 | J308: 36 | K308: 14252 | L308: 14288 | N308: K1 | O308: =VLOOKUP(H308,通道基本信息!B:L,3,FALSE) -> CS15
A309: 308 | B309: =H309&"-"&I309 -> CS15-R004-4-2 | C309: =O309&"-"&D309 -> CS15-RFK5H | D309: RFK5H | E309: =VLOOKUP(H309,通道基本信息!B:K,6,0) -> R | F309: =VLOOKUP(H309,通道基本信息!B:K,5,0) -> F | G309: =VLOOKUP(H309,通道基本信息!B:K,8,0) -> H | H309: CS15-R004-4 | I309: 2 | J309: 36 | K309: 14332 | L309: 14368 | N309: K5 | O309: =VLOOKUP(H309,通道基本信息!B:L,3,FALSE) -> CS15
A310: 309 | B310: =H310&"-"&I310 -> CS15-R004-4-3 | C310: =O310&"-"&D310 -> CS15-RFK7H | D310: RFK7H | E310: =VLOOKUP(H310,通道基本信息!B:K,6,0) -> R | F310: =VLOOKUP(H310,通道基本信息!B:K,5,0) -> F | G310: =VLOOKUP(H310,通道基本信息!B:K,8,0) -> H | H310: CS15-R004-4 | I310: 3 | J310: 36 | K310: 14372 | L310: 14408 | N310: K7 | O310: =VLOOKUP(H310,通道基本信息!B:L,3,FALSE) -> CS15
A311: 310 | B311: =H311&"-"&I311 -> CS15-R004-4-4 | C311: =O311&"-"&D311 -> CS15-RFK11H | D311: RFK11H | E311: =VLOOKUP(H311,通道基本信息!B:K,6,0) -> R | F311: =VLOOKUP(H311,通道基本信息!B:K,5,0) -> F | G311: =VLOOKUP(H311,通道基本信息!B:K,8,0) -> H | H311: CS15-R004-4 | I311: 4 | J311: 36 | K311: 14452 | L311: 14488 | N311: K11 | O311: =VLOOKUP(H311,通道基本信息!B:L,3,FALSE) -> CS15
A312: 311 | B312: =H312&"-"&I312 -> CS15-T001-5-1 | C312: =O312&"-"&D312 -> CS15-TAC9R | D312: TAC9R | E312: =VLOOKUP(H312,通道基本信息!B:K,6,0) -> T | F312: =VLOOKUP(H312,通道基本信息!B:K,5,0) -> A | G312: =VLOOKUP(H312,通道基本信息!B:K,8,0) -> R | H312: CS15-T001-5 | I312: 1 | J312: 36 | K312: 3732 | L312: 3768 | M312: C9 | N312: AC9R | O312: =VLOOKUP(H312,通道基本信息!B:L,3,FALSE) -> CS15
A313: 312 | B313: =H313&"-"&I313 -> CS15-T001-5-2 | C313: =O313&"-"&D313 -> CS15-TAC11R | D313: TAC11R | E313: =VLOOKUP(H313,通道基本信息!B:K,6,0) -> T | F313: =VLOOKUP(H313,通道基本信息!B:K,5,0) -> A | G313: =VLOOKUP(H313,通道基本信息!B:K,8,0) -> R | H313: CS15-T001-5 | I313: 2 | J313: 36 | K313: 3772 | L313: 3808 | M313: C11 | N313: AC11R | O313: =VLOOKUP(H313,通道基本信息!B:L,3,FALSE) -> CS15
A314: 313 | B314: =H314&"-"&I314 -> CS15-T001-5-3 | C314: =O314&"-"&D314 -> CS15-TAC13R | D314: TAC13R | E314: =VLOOKUP(H314,通道基本信息!B:K,6,0) -> T | F314: =VLOOKUP(H314,通道基本信息!B:K,5,0) -> A | G314: =VLOOKUP(H314,通道基本信息!B:K,8,0) -> R | H314: CS15-T001-5 | I314: 3 | J314: 36 | K314: 3812 | L314: 3848 | M314: C13 | N314: AC13R | O314: =VLOOKUP(H314,通道基本信息!B:L,3,FALSE) -> CS15
A315: 314 | B315: =H315&"-"&I315 -> CS15-T001-5-4 | C315: =O315&"-"&D315 -> CS15-TAC15R | D315: TAC15R | E315: =VLOOKUP(H315,通道基本信息!B:K,6,0) -> T | F315: =VLOOKUP(H315,通道基本信息!B:K,5,0) -> A | G315: =VLOOKUP(H315,通道基本信息!B:K,8,0) -> R | H315: CS15-T001-5 | I315: 4 | J315: 36 | K315: 3852 | L315: 3888 | M315: C15 | N315: AC15R | O315: =VLOOKUP(H315,通道基本信息!B:L,3,FALSE) -> CS15
A316: 315 | B316: =H316&"-"&I316 -> CS15-T001-5-5 | C316: =O316&"-"&D316 -> CS15-TAC17R | D316: TAC17R | E316: =VLOOKUP(H316,通道基本信息!B:K,6,0) -> T | F316: =VLOOKUP(H316,通道基本信息!B:K,5,0) -> A | G316: =VLOOKUP(H316,通道基本信息!B:K,8,0) -> R | H316: CS15-T001-5 | I316: 5 | J316: 36 | K316: 3892 | L316: 3928 | M316: C17 | N316: AC17R | O316: =VLOOKUP(H316,通道基本信息!B:L,3,FALSE) -> CS15
A317: 316 | B317: =H317&"-"&I317 -> CS15-T002-2-1 | C317: =O317&"-"&D317 -> CS15-TEC19R | D317: TEC19R | E317: =VLOOKUP(H317,通道基本信息!B:K,6,0) -> T | F317: =VLOOKUP(H317,通道基本信息!B:K,5,0) -> E | G317: =VLOOKUP(H317,通道基本信息!B:K,8,0) -> R | H317: CS15-T002-2 | I317: 1 | J317: 36 | K317: 4072 | L317: 4108 | M317: C19 | N317: EC19R | O317: =VLOOKUP(H317,通道基本信息!B:L,3,FALSE) -> CS15
A318: 317 | B318: =H318&"-"&I318 -> CS15-T002-2-2 | C318: =O318&"-"&D318 -> CS15-TEC21R | D318: TEC21R | E318: =VLOOKUP(H318,通道基本信息!B:K,6,0) -> T | F318: =VLOOKUP(H318,通道基本信息!B:K,5,0) -> E | G318: =VLOOKUP(H318,通道基本信息!B:K,8,0) -> R | H318: CS15-T002-2 | I318: 2 | J318: 36 | K318: 4112 | L318: 4148 | M318: C21 | N318: EC21R | O318: =VLOOKUP(H318,通道基本信息!B:L,3,FALSE) -> CS15
A319: 318 | B319: =H319&"-"&I319 -> CS15-T003-3-1 | C319: =O319&"-"&D319 -> CS15-TWC17R | D319: TWC17R | E319: =VLOOKUP(H319,通道基本信息!B:K,6,0) -> T | F319: =VLOOKUP(H319,通道基本信息!B:K,5,0) -> W | G319: =VLOOKUP(H319,通道基本信息!B:K,8,0) -> R | H319: CS15-T003-3 | I319: 1 | J319: 36 | K319: 3892 | L319: 3928 | M319: C17 | N319: WC17R | O319: =VLOOKUP(H319,通道基本信息!B:L,3,FALSE) -> CS15
A320: 319 | B320: =H320&"-"&I320 -> CS15-T003-3-2 | C320: =O320&"-"&D320 -> CS15-TWC19R | D320: TWC19R | E320: =VLOOKUP(H320,通道基本信息!B:K,6,0) -> T | F320: =VLOOKUP(H320,通道基本信息!B:K,5,0) -> W | G320: =VLOOKUP(H320,通道基本信息!B:K,8,0) -> R | H320: CS15-T003-3 | I320: 2 | J320: 36 | K320: 4072 | L320: 4108 | M320: C19 | N320: WC19R | O320: =VLOOKUP(H320,通道基本信息!B:L,3,FALSE) -> CS15
A321: 320 | B321: =H321&"-"&I321 -> CS15-T003-3-3 | C321: =O321&"-"&D321 -> CS15-TWC21R | D321: TWC21R | E321: =VLOOKUP(H321,通道基本信息!B:K,6,0) -> T | F321: =VLOOKUP(H321,通道基本信息!B:K,5,0) -> W | G321: =VLOOKUP(H321,通道基本信息!B:K,8,0) -> R | H321: CS15-T003-3 | I321: 3 | J321: 36 | K321: 4112 | L321: 4148 | M321: C21 | N321: WC21R | O321: =VLOOKUP(H321,通道基本信息!B:L,3,FALSE) -> CS15
A322: 319 | B322: =H322&"-"&I322 -> CS19-R001-2-1 | C322: =O322&"-"&D322 -> CS19-RWC1R | D322: RWC1R | E322: =VLOOKUP(H322,通道基本信息!B:K,6,0) -> R | F322: =VLOOKUP(H322,通道基本信息!B:K,5,0) -> W | G322: =VLOOKUP(H322,通道基本信息!B:K,8,0) -> R | H322: CS19-R001-2 | I322: 1 | J322: 36 | K322: 6333.5 | L322: 6369.5 | M322: C1 | N322: WC1R | O322: =VLOOKUP(H322,通道基本信息!B:L,3,FALSE) -> CS19
A323: 320 | B323: =H323&"-"&I323 -> CS19-R001-2-2 | C323: =O323&"-"&D323 -> CS19-RWC2R | D323: RWC2R | E323: =VLOOKUP(H323,通道基本信息!B:K,6,0) -> R | F323: =VLOOKUP(H323,通道基本信息!B:K,5,0) -> W | G323: =VLOOKUP(H323,通道基本信息!B:K,8,0) -> R | H323: CS19-R001-2 | I323: 2 | J323: 36 | K323: 6374.5 | L323: 6410.5 | M323: C2 | N323: WC2R | O323: =VLOOKUP(H323,通道基本信息!B:L,3,FALSE) -> CS19
... A820: 817 | B820: =H820&"-"&I820 -> CS9C-T008-1-1 | C820: =O820&"-"&D820 -> CS9C-THKu-KaR | D820: THKu-KaR | E820: =VLOOKUP(H820,通道基本信息!B:K,6,0) -> T | F820: =VLOOKUP(H820,通道基本信息!B:K,5,0) -> H | G820: =VLOOKUP(H820,通道基本信息!B:K,8,0) -> R | H820: CS9C-T008-1 | I820: 1 | J820: 200 | K820: 21490 | L820: 21690 | M820: Ku-Ka | N820: HKu-KaR | O820: =VLOOKUP(H820,通道基本信息!B:L,3,FALSE) -> CS9C
A821: 818 | B821: =H821&"-"&I821 -> CS19-R007-1-1 | C821: =O821&"-"&D821 -> CS19-RY1L | D821: RY1L | E821: =VLOOKUP(H821,通道基本信息!B:K,6,0) -> R | F821: =VLOOKUP(H821,通道基本信息!B:K,5,0) -> Y | G821: =VLOOKUP(H821,通道基本信息!B:K,8,0) -> L | H821: CS19-R007-1 | I821: 1 | J821: 50 | K821: 29095 | L821: 29145 | N821: Y1L | O821: =VLOOKUP(H821,通道基本信息!B:L,3,FALSE) -> CS19
A822: 819 | B822: =H822&"-"&I822 -> CS19-R008-1-1 | C822: =O822&"-"&D822 -> CS19-RY2L | D822: RY2L | E822: =VLOOKUP(H822,通道基本信息!B:K,6,0) -> R | F822: =VLOOKUP(H822,通道基本信息!B:K,5,0) -> Y | G822: =VLOOKUP(H822,通道基本信息!B:K,8,0) -> L | H822: CS19-R008-1 | I822: 1 | J822: 50 | K822: 29151 | L822: 29201 | N822: Y2L | O822: =VLOOKUP(H822,通道基本信息!B:L,3,FALSE) -> CS19
A823: 820 | B823: =H823&"-"&I823 -> CS19-R009-1-1 | C823: =O823&"-"&D823 -> CS19-RY3L | D823: RY3L | E823: =VLOOKUP(H823,通道基本信息!B:K,6,0) -> R | F823: =VLOOKUP(H823,通道基本信息!B:K,5,0) -> Y | G823: =VLOOKUP(H823,通道基本信息!B:K,8,0) -> L | H823: CS19-R009-1 | I823: 1 | J823: 50 | K823: 29207 | L823: 29257 | N823: Y3L | O823: =VLOOKUP(H823,通道基本信息!B:L,3,FALSE) -> CS19
A824: 821 | B824: =H824&"-"&I824 -> CS19-R010-1-1 | C824: =O824&"-"&D824 -> CS19-RY4L | D824: RY4L | E824: =VLOOKUP(H824,通道基本信息!B:K,6,0) -> R | F824: =VLOOKUP(H824,通道基本信息!B:K,5,0) -> Y | G824: =VLOOKUP(H824,通道基本信息!B:K,8,0) -> L | H824: CS19-R010-1 | I824: 1 | J824: 50 | K824: 29023 | L824: 29073 | N824: Y4L | O824: =VLOOKUP(H824,通道基本信息!B:L,3,FALSE) -> CS19
A825: 822 | B825: =H825&"-"&I825 -> CS19-R011-1-1 | C825: =O825&"-"&D825 -> CS19-RY5R | D825: RY5R | E825: =VLOOKUP(H825,通道基本信息!B:K,6,0) -> R | F825: =VLOOKUP(H825,通道基本信息!B:K,5,0) -> Y | G825: =VLOOKUP(H825,通道基本信息!B:K,8,0) -> R | H825: CS19-R011-1 | I825: 1 | J825: 50 | K825: 29207 | L825: 29257 | N825: Y5R | O825: =VLOOKUP(H825,通道基本信息!B:L,3,FALSE) -> CS19
A826: 823 | B826: =H826&"-"&I826 -> CS19-R012-1-1 | C826: =O826&"-"&D826 -> CS19-RY6R | D826: RY6R | E826: =VLOOKUP(H826,通道基本信息!B:K,6,0) -> R | F826: =VLOOKUP(H826,通道基本信息!B:K,5,0) -> Y | G826: =VLOOKUP(H826,通道基本信息!B:K,8,0) -> R | H826: CS19-R012-1 | I826: 1 | J826: 50 | K826: 29095 | L826: 29145 | N826: Y6R | O826: =VLOOKUP(H826,通道基本信息!B:L,3,FALSE) -> CS19
A827: 824 | B827: =H827&"-"&I827 -> CS19-R013-1-1 | C827: =O827&"-"&D827 -> CS19-RY7R | D827: RY7R | E827: =VLOOKUP(H827,通道基本信息!B:K,6,0) -> R | F827: =VLOOKUP(H827,通道基本信息!B:K,5,0) -> Y | G827: =VLOOKUP(H827,通道基本信息!B:K,8,0) -> R | H827: CS19-R013-1 | I827: 1 | J827: 50 | K827: 29263 | L827: 29313 | N827: Y7R | O827: =VLOOKUP(H827,通道基本信息!B:L,3,FALSE) -> CS19
A828: 825 | B828: =H828&"-"&I828 -> CS19-R014-1-1 | C828: =O828&"-"&D828 -> CS19-RY8L | D828: RY8L | E828: =VLOOKUP(H828,通道基本信息!B:K,6,0) -> R | F828: =VLOOKUP(H828,通道基本信息!B:K,5,0) -> Y | G828: =VLOOKUP(H828,通道基本信息!B:K,8,0) -> L | H828: CS19-R014-1 | I828: 1 | J828: 50 | K828: 29263 | L828: 29313 | N828: Y8L | O828: =VLOOKUP(H828,通道基本信息!B:L,3,FALSE) -> CS19
A829: 826 | B829: =H829&"-"&I829 -> CS19-R015-1-1 | C829: =O829&"-"&D829 -> CS19-RY9R | D829: RY9R | E829: =VLOOKUP(H829,通道基本信息!B:K,6,0) -> R | F829: =VLOOKUP(H829,通道基本信息!B:K,5,0) -> Y | G829: =VLOOKUP(H829,通道基本信息!B:K,8,0) -> R | H829: CS19-R015-1 | I829: 1 | J829: 50 | K829: 29151 | L829: 29201 | N829: Y9R | O829: =VLOOKUP(H829,通道基本信息!B:L,3,FALSE) -> CS19
...

Sheet 矩阵信息表
A1: ID | B1: 矩阵代码 | C1: 卫星 | D1: 区号 | E1: 组号 | F1: 输入端口数 | G1: 输出端口数 | H1: 生效状态 | I1: 备注
A2: 1 | B2: =C2&"-"&D2&"-"&E2 -> CS10R-1-1 | C2: CS10R | D2: 1 | E2: 1 | F2: 13 | G2: 13 | H2: 1 | I2: C1A-C14A
A3: 2 | B3: =C3&"-"&D3&"-"&E3 -> CS10R-1-2 | C3: CS10R | D3: 1 | E3: 2 | F3: 4 | G3: 4 | H3: 1 | I3: C5B-C8B
A4: 3 | B4: =C4&"-"&D4&"-"&E4 -> CS10R-1-3 | C4: CS10R | D4: 1 | E4: 3 | F4: 2 | G4: 2 | H4: 1 | I4: W1B-W2B
A5: 4 | B5: =C5&"-"&D5&"-"&E5 -> CS10R-1-4 | C5: CS10R | D5: 1 | E5: 4 | F5: 8 | G5: 8 | H5: 1 | I5: C1B/S1B-C4B/S4B
A6: 5 | B6: =C6&"-"&D6&"-"&E6 -> CS10R-1-5 | C6: CS10R | D6: 1 | E6: 5 | F6: 8 | G6: 8 | H6: 1 | I6: C11B/W11B-C14B/W14B
A7: 6 | B7: =C7&"-"&D7&"-"&E7 -> CS10R-1-6 | C7: CS10R | D7: 1 | E7: 6 | F7: 8 | G7: 8 | H7: 1 | I7: I5A-I8A/I11B-I14B
A8: 7 | B8: =C8&"-"&D8&"-"&E8 -> CS10R-1-7 | C8: CS10R | D8: 1 | E8: 7 | F8: 8 | G8: 8 | H8: 1 | I8: I11A-I14A/E11B-E13B,W3B
A9: 8 | B9: =C9&"-"&D9&"-"&E9 -> CS6D-1-1 | C9: CS6D | D9: 1 | E9: 1 | F9: 63 | G9: 25 | H9: 1 | I9: C频段大波束
A10: 9 | B10: =C10&"-"&D10&"-"&E10 -> CS6D-1-2 | C10: CS6D | D10: 1 | E10: 2 | F10: 31 | G10: 31 | H10: 1 | I10: Ku大波束
A11: 10 | B11: =C11&"-"&D11&"-"&E11 -> CS6E-1-1 | C11: CS6E | D11: 1 | E11: 1 | F11: 13 | G11: 13 | H11: 1 | I11: 海上波束前向
A12: 11 | B12: =C12&"-"&D12&"-"&E12 -> CS6E-1-2 | C12: CS6E | D12: 1 | E12: 2 | F12: 13 | G12: 13 | H12: 1 | I12: 海上波束返向
A13: 12 | B13: =C13&"-"&D13&"-"&E13 -> CS6E-1-3 | C13: CS6E | D13: 1 | E13: 3 | F13: 11 | G13: 11 | H13: 1 | I13: 陆地波束返向
... A190: 189 | B190: =C190&"-"&D190&"-"&E190 -> E10B-1-117 | C190: E10B | D190: 1 | E190: 117 | F190: 1 | G190: 1 | H190: 1 | I190: 19_19_ChSat_0001

Sheet 端口信息表
A1: ID | B1: 端口代码 | C1: 所属矩阵 | D1: 输入I/输出O | E1: 序号 | F1: 关联通道代码（短）
A2: 1 | B2: =C2&"-"&D2&E2 -> CS10R-1-1-I1 | C2: CS10R-1-1 | D2: I | E2: 1 | F2: RC1A
A3: 2 | B3: =C3&"-"&D3&E3 -> CS10R-1-1-I2 | C3: CS10R-1-1 | D3: I | E3: 2 | F3: RC2A
A4: 3 | B4: =C4&"-"&D4&E4 -> CS10R-1-1-I3 | C4: CS10R-1-1 | D4: I | E4: 3 | F4: RC3A
A5: 4 | B5: =C5&"-"&D5&E5 -> CS10R-1-1-I4 | C5: CS10R-1-1 | D5: I | E5: 4 | F5: RC4A
A6: 5 | B6: =C6&"-"&D6&E6 -> CS10R-1-1-I5 | C6: CS10R-1-1 | D6: I | E6: 5 | F6: RC5A
A7: 6 | B7: =C7&"-"&D7&E7 -> CS10R-1-1-I6 | C7: CS10R-1-1 | D7: I | E7: 6 | F7: RC6A
A8: 7 | B8: =C8&"-"&D8&E8 -> CS10R-1-1-I7 | C8: CS10R-1-1 | D8: I | E8: 7 | F8: RC7A
A9: 8 | B9: =C9&"-"&D9&E9 -> CS10R-1-1-I8 | C9: CS10R-1-1 | D9: I | E9: 8 | F9: RC8A
A10: 9 | B10: =C10&"-"&D10&E10 -> CS10R-1-1-I9 | C10: CS10R-1-1 | D10: I | E10: 9 | F10: RC9A
A11: 10 | B11: =C11&"-"&D11&E11 -> CS10R-1-1-I10 | C11: CS10R-1-1 | D11: I | E11: 10 | F11: RC11A
A12: 11 | B12: =C12&"-"&D12&E12 -> CS10R-1-1-I11 | C12: CS10R-1-1 | D12: I | E12: 11 | F12: RC12A
A13: 12 | B13: =C13&"-"&D13&E13 -> CS10R-1-1-I12 | C13: CS10R-1-1 | D13: I | E13: 12 | F13: RC13A
... A2704: 2697 | B2704: =C2704&"-"&D2704&E2704 -> CS19-1-4-O28 | C2704: CS19-1-4 | D2704: O | E2704: 28 | F2704: TH28R
A2705: 2698 | B2705: =C2705&"-"&D2705&E2705 -> CS26-1-1-I1 | C2705: CS26-1-1 | D2705: I | E2705: 1 | F2705: RD2L | G2705: =VLOOKUP(F2705,通道清单!D:D,1,0) -> RD2L
A2706: 2699 | B2706: =C2706&"-"&D2706&E2706 -> CS26-1-1-I2 | C2706: CS26-1-1 | D2706: I | E2706: 2 | F2706: RD5L | G2706: =VLOOKUP(F2706,通道清单!D:D,1,0) -> RD5L
A2707: 2700 | B2707: =C2707&"-"&D2707&E2707 -> CS26-1-1-I3 | C2707: CS26-1-1 | D2707: I | E2707: 3 | F2707: RD18L | G2707: =VLOOKUP(F2707,通道清单!D:D,1,0) -> RD18L
A2708: 2701 | B2708: =C2708&"-"&D2708&E2708 -> CS26-1-1-I4 | C2708: CS26-1-1 | D2708: I | E2708: 4 | F2708: RD33L | G2708: =VLOOKUP(F2708,通道清单!D:D,1,0) -> RD33L
A2709: 2702 | B2709: =C2709&"-"&D2709&E2709 -> CS26-1-1-I5 | C2709: CS26-1-1 | D2709: I | E2709: 5 | F2709: RD11R | G2709: =VLOOKUP(F2709,通道清单!D:D,1,0) -> RD11R
A2710: 2703 | B2710: =C2710&"-"&D2710&E2710 -> CS26-1-1-I6 | C2710: CS26-1-1 | D2710: I | E2710: 6 | F2710: RD24R | G2710: =VLOOKUP(F2710,通道清单!D:D,1,0) -> RD24R
A2711: 2704 | B2711: =C2711&"-"&D2711&E2711 -> CS26-1-1-I7 | C2711: CS26-1-1 | D2711: I | E2711: 7 | F2711: RD27R | G2711: =VLOOKUP(F2711,通道清单!D:D,1,0) -> RD27R
A2712: 2705 | B2712: =C2712&"-"&D2712&E2712 -> CS26-1-1-I8 | C2712: CS26-1-1 | D2712: I | E2712: 8 | F2712: RD39R | G2712: =VLOOKUP(F2712,通道清单!D:D,1,0) -> RD39R
A2713: 2706 | B2713: =C2713&"-"&D2713&E2713 -> CS26-1-1-O1 | C2713: CS26-1-1 | D2713: O | E2713: 1 | F2713: TY2R | G2713: =VLOOKUP(F2713,通道清单!D:D,1,0) -> TY2R
A2714: 2707 | B2714: =C2714&"-"&D2714&E2714 -> CS26-1-1-O2 | C2714: CS26-1-1 | D2714: O | E2714: 2 | F2714: TY5R | G2714: =VLOOKUP(F2714,通道清单!D:D,1,0) -> TY5R
A2715: 2708 | B2715: =C2715&"-"&D2715&E2715 -> CS26-1-1-O3 | C2715: CS26-1-1 | D2715: O | E2715: 3 | F2715: TY18R | G2715: =VLOOKUP(F2715,通道清单!D:D,1,0) -> TY18R
A2716: 2709 | B2716: =C2716&"-"&D2716&E2716 -> CS26-1-1-O4 | C2716: CS26-1-1 | D2716: O | E2716: 4 | F2716: TY33R | G2716: =VLOOKUP(F2716,通道清单!D:D,1,0) -> TY33R
... A3456: 3449 | B3456: =C3456&"-"&D3456&E3456 -> CS26-1-28-O16 | C3456: CS26-1-28 | D3456: O | E3456: 16 | F3456: TB59R | G3456: =VLOOKUP(F3456,通道清单!D:D,1,0) -> TB59R
A3457: 3450 | B3457: =C3457&"-"&D3457&E3457 -> IS35E-1-1-I1 | C3457: IS35E-1-1 | D3457: I | E3457: 1 | F3457: RC02L1C01R2
A3458: 3451 | B3458: =C3458&"-"&D3458&E3458 -> IS35E-1-1-O1 | C3458: IS35E-1-1 | D3458: O | E3458: 1 | F3458: TC02L1C01R2
A3459: 3452 | B3459: =C3459&"-"&D3459&E3459 -> IS35E-1-2-I1 | C3459: IS35E-1-2 | D3459: I | E3459: 1 | F3459: RC01LGCR
A3460: 3453 | B3460: =C3460&"-"&D3460&E3460 -> IS35E-1-2-O1 | C3460: IS35E-1-2 | D3460: O | E3460: 1 | F3460: TC01LGCR
A3461: 3454 | B3461: =C3461&"-"&D3461&E3461 -> IS35E-1-3-I1 | C3461: IS35E-1-3 | D3461: I | E3461: 1 | F3461: RC09L1C01R1
A3462: 3455 | B3462: =C3462&"-"&D3462&E3462 -> IS35E-1-3-O1 | C3462: IS35E-1-3 | D3462: O | E3462: 1 | F3462: TC09L1C01R1
A3463: 3456 | B3463: =C3463&"-"&D3463&E3463 -> IS35E-1-4-I1 | C3463: IS35E-1-4 | D3463: I | E3463: 1 | F3463: RC11L2C01R1
A3464: 3457 | B3464: =C3464&"-"&D3464&E3464 -> IS35E-1-4-O1 | C3464: IS35E-1-4 | D3464: O | E3464: 1 | F3464: TC11L2C01R1
A3465: 3458 | B3465: =C3465&"-"&D3465&E3465 -> IS39-1-5-I1 | C3465: IS39-1-5 | D3465: I | E3465: 1 | F3465: REHCL31WHCR
A3466: 3459 | B3466: =C3466&"-"&D3466&E3466 -> IS39-1-5-O1 | C3466: IS39-1-5 | D3466: O | E3466: 1 | F3466: TEHCL31WHCR
A3467: 3460 | B3467: =C3467&"-"&D3467&E3467 -> IS39-1-6-I1 | C3467: IS39-1-6 | D3467: I | E3467: 1 | F3467: REHCL31WHCR
A3468: 3461 | B3468: =C3468&"-"&D3468&E3468 -> IS39-1-6-O1 | C3468: IS39-1-6 | D3468: O | E3468: 1 | F3468: TEHCL31WHCR
... A3690: 3683 | B3690: =C3690&"-"&D3690&E3690 -> E10B-1-117-O1 | C3690: E10B-1-117 | D3690: O | E3690: 1 | F3690: T19_19_ChSat_0001

Sheet 开关状态表
A1: ID | B1: 开关代码 | C1: 所属矩阵 | D1: 入端口序号 | E1: 出端口序号 | F1: 索引"入端口通道“ | G1: 索引"出端口通道" | H1: 开关状态 1-通，0-断 | I1: 常通/可切 | J1: 使用TWT | K1: P0 | L1: P1 | M1: P2 | N1: TWT有效状态 | O1: 查找辅助列
A2: =ROW()-1 -> 1 | B2: =C2&"-["&D2&"]["&E2&"]" -> CS10R-1-1-[1][1] | C2: CS10R-1-1 | D2: 1 | E2: 1 | F2: =VLOOKUP(C2&"-I"&D2,端口信息表!B:F,5,FALSE) -> RC1A | G2: =VLOOKUP(C2&"-O"&E2,端口信息表!B:F,5,FALSE) -> TC1A | H2: =IF(I2="常通",1,VLOOKUP(B2,'开关组信息表（新）'!C:I,7,0)) -> 1 | I2: 常通 | J2: =IF(N2=$M$1,M2,IF(N2=$L$1,L2,K2)) -> TWT-A1 | K2: TWT-A1 | L2: TWT-A4 | M2: TWT-A2 | N2: P0 | O2: =F2&"-"&G2 -> RC1A-TC1A
A3: =ROW()-1 -> 2 | B3: =C3&"-["&D3&"]["&E3&"]" -> CS10R-1-1-[2][2] | C3: CS10R-1-1 | D3: 2 | E3: 2 | F3: =VLOOKUP(C3&"-I"&D3,端口信息表!B:F,5,FALSE) -> RC2A | G3: =VLOOKUP(C3&"-O"&E3,端口信息表!B:F,5,FALSE) -> TC2A | H3: =IF(I3="常通",1,VLOOKUP(B3,'开关组信息表（新）'!C:I,7,0)) -> 1 | I3: 常通 | J3: =IF(N3=$M$1,M3,IF(N3=$L$1,L3,K3)) -> TWT-A2 | K3: TWT-A2 | L3: TWT-A4 | M3: TWT-A3 | N3: P0 | O3: =F3&"-"&G3 -> RC2A-TC2A
A4: =ROW()-1 -> 3 | B4: =C4&"-["&D4&"]["&E4&"]" -> CS10R-1-1-[3][3] | C4: CS10R-1-1 | D4: 3 | E4: 3 | F4: =VLOOKUP(C4&"-I"&D4,端口信息表!B:F,5,FALSE) -> RC3A | G4: =VLOOKUP(C4&"-O"&E4,端口信息表!B:F,5,FALSE) -> TC3A | H4: =IF(I4="常通",1,VLOOKUP(B4,'开关组信息表（新）'!C:I,7,0)) -> 1 | I4: 常通 | J4: =IF(N4=$M$1,M4,IF(N4=$L$1,L4,K4)) -> TWT-A3 | K4: TWT-A3 | L4: TWT-A4 | M4: TWT-A5 | N4: P0 | O4: =F4&"-"&G4 -> RC3A-TC3A
A5: =ROW()-1 -> 4 | B5: =C5&"-["&D5&"]["&E5&"]" -> CS10R-1-1-[4][4] | C5: CS10R-1-1 | D5: 4 | E5: 4 | F5: =VLOOKUP(C5&"-I"&D5,端口信息表!B:F,5,FALSE) -> RC4A | G5: =VLOOKUP(C5&"-O"&E5,端口信息表!B:F,5,FALSE) -> TC4A | H5: =IF(I5="常通",1,VLOOKUP(B5,'开关组信息表（新）'!C:I,7,0)) -> 1 | I5: 常通 | J5: =IF(N5=$M$1,M5,IF(N5=$L$1,L5,K5)) -> TWT-A5 | K5: TWT-A5 | L5: TWT-A4 | M5: TWT-A3 | N5: P0 | O5: =F5&"-"&G5 -> RC4A-TC4A
A6: =ROW()-1 -> 5 | B6: =C6&"-["&D6&"]["&E6&"]" -> CS10R-1-1-[5][5] | C6: CS10R-1-1 | D6: 5 | E6: 5 | F6: =VLOOKUP(C6&"-I"&D6,端口信息表!B:F,5,FALSE) -> RC5A | G6: =VLOOKUP(C6&"-O"&E6,端口信息表!B:F,5,FALSE) -> TC5A | H6: =IF(I6="常通",1,VLOOKUP(B6,'开关组信息表（新）'!C:I,7,0)) -> 1 | I6: 常通 | J6: =IF(N6=$M$1,M6,IF(N6=$L$1,L6,K6)) -> TWT-A6 | K6: TWT-A6 | L6: TWT-A4 | M6: TWT-A3 | N6: P0 | O6: =F6&"-"&G6 -> RC5A-TC5A
A7: =ROW()-1 -> 6 | B7: =C7&"-["&D7&"]["&E7&"]" -> CS10R-1-1-[6][6] | C7: CS10R-1-1 | D7: 6 | E7: 6 | F7: =VLOOKUP(C7&"-I"&D7,端口信息表!B:F,5,FALSE) -> RC6A | G7: =VLOOKUP(C7&"-O"&E7,端口信息表!B:F,5,FALSE) -> TC6A | H7: =IF(I7="常通",1,VLOOKUP(B7,'开关组信息表（新）'!C:I,7,0)) -> 1 | I7: 常通 | J7: =IF(N7=$M$1,M7,IF(N7=$L$1,L7,K7)) -> TWT-A7 | K7: TWT-A7 | L7: TWT-A8 | M7: TWT-A9 | N7: P0 | O7: =F7&"-"&G7 -> RC6A-TC6A
A8: =ROW()-1 -> 7 | B8: =C8&"-["&D8&"]["&E8&"]" -> CS10R-1-1-[7][7] | C8: CS10R-1-1 | D8: 7 | E8: 7 | F8: =VLOOKUP(C8&"-I"&D8,端口信息表!B:F,5,FALSE) -> RC7A | G8: =VLOOKUP(C8&"-O"&E8,端口信息表!B:F,5,FALSE) -> TC7A | H8: =IF(I8="常通",1,VLOOKUP(B8,'开关组信息表（新）'!C:I,7,0)) -> 1 | I8: 常通 | J8: =IF(N8=$M$1,M8,IF(N8=$L$1,L8,K8)) -> TWT-A9 | K8: TWT-A9 | L8: TWT-A8 | M8: TWT-A7 | N8: P0 | O8: =F8&"-"&G8 -> RC7A-TC7A
A9: =ROW()-1 -> 8 | B9: =C9&"-["&D9&"]["&E9&"]" -> CS10R-1-1-[8][8] | C9: CS10R-1-1 | D9: 8 | E9: 8 | F9: =VLOOKUP(C9&"-I"&D9,端口信息表!B:F,5,FALSE) -> RC8A | G9: =VLOOKUP(C9&"-O"&E9,端口信息表!B:F,5,FALSE) -> TC8A | H9: =IF(I9="常通",1,VLOOKUP(B9,'开关组信息表（新）'!C:I,7,0)) -> 1 | I9: 常通 | J9: =IF(N9=$M$1,M9,IF(N9=$L$1,L9,K9)) -> TWT-A10 | K9: TWT-A10 | L9: TWT-A8 | M9: TWT-A11 | N9: P0 | O9: =F9&"-"&G9 -> RC8A-TC8A
A10: =ROW()-1 -> 9 | B10: =C10&"-["&D10&"]["&E10&"]" -> CS10R-1-1-[9][9] | C10: CS10R-1-1 | D10: 9 | E10: 9 | F10: =VLOOKUP(C10&"-I"&D10,端口信息表!B:F,5,FALSE) -> RC9A | G10: =VLOOKUP(C10&"-O"&E10,端口信息表!B:F,5,FALSE) -> TC9A | H10: =IF(I10="常通",1,VLOOKUP(B10,'开关组信息表（新）'!C:I,7,0)) -> 1 | I10: 常通 | J10: =IF(N10=$M$1,M10,IF(N10=$L$1,L10,K10)) -> TWT-A11 | K10: TWT-A11 | L10: TWT-A12 | M10: TWT-A10 | N10: P0 | O10: =F10&"-"&G10 -> RC9A-TC9A
A11: =ROW()-1 -> 10 | B11: =C11&"-["&D11&"]["&E11&"]" -> CS10R-1-1-[10][10] | C11: CS10R-1-1 | D11: 10 | E11: 10 | F11: =VLOOKUP(C11&"-I"&D11,端口信息表!B:F,5,FALSE) -> RC11A | G11: =VLOOKUP(C11&"-O"&E11,端口信息表!B:F,5,FALSE) -> TC11A | H11: =IF(I11="常通",1,VLOOKUP(B11,'开关组信息表（新）'!C:I,7,0)) -> 1 | I11: 常通 | J11: =IF(N11=$M$1,M11,IF(N11=$L$1,L11,K11)) -> TWT-B1 | K11: TWT-B1 | L11: TWT-B3 | M11: TWT-B4 | N11: P0 | O11: =F11&"-"&G11 -> RC11A-TC11A
A12: =ROW()-1 -> 11 | B12: =C12&"-["&D12&"]["&E12&"]" -> CS10R-1-1-[11][11] | C12: CS10R-1-1 | D12: 11 | E12: 11 | F12: =VLOOKUP(C12&"-I"&D12,端口信息表!B:F,5,FALSE) -> RC12A | G12: =VLOOKUP(C12&"-O"&E12,端口信息表!B:F,5,FALSE) -> TC12A | H12: =IF(I12="常通",1,VLOOKUP(B12,'开关组信息表（新）'!C:I,7,0)) -> 1 | I12: 常通 | J12: =IF(N12=$M$1,M12,IF(N12=$L$1,L12,K12)) -> TWT-B2 | K12: TWT-B2 | L12: TWT-B3 | M12: TWT-B1 | N12: P0 | O12: =F12&"-"&G12 -> RC12A-TC12A
A13: =ROW()-1 -> 12 | B13: =C13&"-["&D13&"]["&E13&"]" -> CS10R-1-1-[12][12] | C13: CS10R-1-1 | D13: 12 | E13: 12 | F13: =VLOOKUP(C13&"-I"&D13,端口信息表!B:F,5,FALSE) -> RC13A | G13: =VLOOKUP(C13&"-O"&E13,端口信息表!B:F,5,FALSE) -> TC13A | H13: =IF(I13="常通",1,VLOOKUP(B13,'开关组信息表（新）'!C:I,7,0)) -> 1 | I13: 常通 | J13: =IF(N13=$M$1,M13,IF(N13=$L$1,L13,K13)) -> TWT-B4 | K13: TWT-B4 | L13: TWT-B3 | M13: TWT-B5 | N13: P0 | O13: =F13&"-"&G13 -> RC13A-TC13A
... A141: =ROW()-1 -> 140 | B141: =C141&"-["&D141&"]["&E141&"]" -> CS6D-1-2-[18][18] | C141: CS6D-1-2 | D141: 18 | E141: 18 | F141: =VLOOKUP(C141&"-I"&D141,端口信息表!B:F,5,FALSE) -> RZ5B | G141: =VLOOKUP(C141&"-O"&E141,端口信息表!B:F,5,FALSE) -> TZ5B | H141: =IF(I141="常通",1,VLOOKUP(B141,'开关组信息表（新）'!C:I,7,0)) -> 1 | I141: 常通 | J141: =IF(N141=$M$1,M141,IF(N141=$L$1,L141,K141)) -> TWT 18-Ku | K141: TWT 18-Ku | L141: TWT 16-Ku | M141: TWT 17-Ku | N141: P0 | O141: =F141&"-"&G141 -> RZ5B-TZ5B
A142: =ROW()-1 -> 141 | B142: =C142&"-["&D142&"]["&E142&"]" -> CS6D-1-2-[19][19] | C142: CS6D-1-2 | D142: 19 | E142: 19 | F142: =VLOOKUP(C142&"-I"&D142,端口信息表!B:F,5,FALSE) -> RZ6B | G142: =VLOOKUP(C142&"-O"&E142,端口信息表!B:F,5,FALSE) -> TZ6B | H142: 1 | I142: 常通 | J142: =IF(N142=$M$1,M142,IF(N142=$L$1,L142,K142)) -> TWT 19-Ku | K142: TWT 19-Ku | L142: TWT 23-Ku | M142: TWT 20-Ku | N142: P0 | O142: =F142&"-"&G142 -> RZ6B-TZ6B
A143: =ROW()-1 -> 142 | B143: =C143&"-["&D143&"]["&E143&"]" -> CS6D-1-2-[20][20] | C143: CS6D-1-2 | D143: 20 | E143: 20 | F143: =VLOOKUP(C143&"-I"&D143,端口信息表!B:F,5,FALSE) -> RZ7B | G143: =VLOOKUP(C143&"-O"&E143,端口信息表!B:F,5,FALSE) -> TZ7B | H143: =IF(I143="常通",1,VLOOKUP(B143,'开关组信息表（新）'!C:I,7,0)) -> 0 | I143: 可切 | J143: =IF(N143=$M$1,M143,IF(N143=$L$1,L143,K143)) -> TWT 20-Ku | K143: TWT 20-Ku | L143: TWT 23-Ku | M143: TWT 19-Ku | N143: P0 | O143: =F143&"-"&G143 -> RZ7B-TZ7B
A144: =ROW()-1 -> 143 | B144: =C144&"-["&D144&"]["&E144&"]" -> CS6D-1-2-[21][21] | C144: CS6D-1-2 | D144: 21 | E144: 21 | F144: =VLOOKUP(C144&"-I"&D144,端口信息表!B:F,5,FALSE) -> RZ8B | G144: =VLOOKUP(C144&"-O"&E144,端口信息表!B:F,5,FALSE) -> TZ8B | H144: =IF(I144="常通",1,VLOOKUP(B144,'开关组信息表（新）'!C:I,7,0)) -> 1 | I144: 可切 | J144: =IF(N144=$M$1,M144,IF(N144=$L$1,L144,K144)) -> TWT 21-Ku | K144: TWT 21-Ku | L144: TWT 23-Ku | M144: TWT 22-Ku | N144: P0 | O144: =F144&"-"&G144 -> RZ8B-TZ8B
A145: =ROW()-1 -> 144 | B145: =C145&"-["&D145&"]["&E145&"]" -> CS6D-1-2-[22][22] | C145: CS6D-1-2 | D145: 22 | E145: 22 | F145: =VLOOKUP(C145&"-I"&D145,端口信息表!B:F,5,FALSE) -> RZ9B | G145: =VLOOKUP(C145&"-O"&E145,端口信息表!B:F,5,FALSE) -> TZ9B | H145: =IF(I145="常通",1,VLOOKUP(B145,'开关组信息表（新）'!C:I,7,0)) -> 0 | I145: 可切 | J145: =IF(N145=$M$1,M145,IF(N145=$L$1,L145,K145)) -> TWT 22-Ku | K145: TWT 22-Ku | L145: TWT 23-Ku | M145: TWT 21-Ku | N145: P0 | O145: =F145&"-"&G145 -> RZ9B-TZ9B
A146: =ROW()-1 -> 145 | B146: =C146&"-["&D146&"]["&E146&"]" -> CS6D-1-2-[23][23] | C146: CS6D-1-2 | D146: 23 | E146: 23 | F146: =VLOOKUP(C146&"-I"&D146,端口信息表!B:F,5,FALSE) -> RZ10B | G146: =VLOOKUP(C146&"-O"&E146,端口信息表!B:F,5,FALSE) -> TZ10B | H146: =IF(I146="常通",1,VLOOKUP(B146,'开关组信息表（新）'!C:I,7,0)) -> 0 | I146: 可切 | J146: =IF(N146=$M$1,M146,IF(N146=$L$1,L146,K146)) -> TWT 24-Ku | K146: TWT 24-Ku | L146: TWT 23-Ku | M146: TWT 25-Ku | N146: P0 | O146: =F146&"-"&G146 -> RZ10B-TZ10B
A147: =ROW()-1 -> 146 | B147: =C147&"-["&D147&"]["&E147&"]" -> CS6D-1-2-[24][24] | C147: CS6D-1-2 | D147: 24 | E147: 24 | F147: =VLOOKUP(C147&"-I"&D147,端口信息表!B:F,5,FALSE) -> RZ11B | G147: =VLOOKUP(C147&"-O"&E147,端口信息表!B:F,5,FALSE) -> TZ11B | H147: =IF(I147="常通",1,VLOOKUP(B147,'开关组信息表（新）'!C:I,7,0)) -> 0 | I147: 可切 | J147: =IF(N147=$M$1,M147,IF(N147=$L$1,L147,K147)) -> TWT 25-Ku | K147: TWT 25-Ku | L147: TWT 23-Ku | M147: TWT 26-Ku | N147: P0 | O147: =F147&"-"&G147 -> RZ11B-TZ11B
A148: =ROW()-1 -> 147 | B148: =C148&"-["&D148&"]["&E148&"]" -> CS6D-1-2-[25][25] | C148: CS6D-1-2 | D148: 25 | E148: 25 | F148: =VLOOKUP(C148&"-I"&D148,端口信息表!B:F,5,FALSE) -> RZ12B | G148: =VLOOKUP(C148&"-O"&E148,端口信息表!B:F,5,FALSE) -> TZ12B | H148: =IF(I148="常通",1,VLOOKUP(B148,'开关组信息表（新）'!C:I,7,0)) -> 0 | I148: 可切 | J148: =IF(N148=$M$1,M148,IF(N148=$L$1,L148,K148)) -> TWT 26-Ku | K148: TWT 26-Ku | L148: TWT 23-Ku | M148: TWT 25-Ku | N148: P0 | O148: =F148&"-"&G148 -> RZ12B-TZ12B
A149: =ROW()-1 -> 148 | B149: =C149&"-["&D149&"]["&E149&"]" -> CS6D-1-2-[26][26] | C149: CS6D-1-2 | D149: 26 | E149: 26 | F149: =VLOOKUP(C149&"-I"&D149,端口信息表!B:F,5,FALSE) -> RS7B | G149: =VLOOKUP(C149&"-O"&E149,端口信息表!B:F,5,FALSE) -> TS7B | H149: =IF(I149="常通",1,VLOOKUP(B149,'开关组信息表（新）'!C:I,7,0)) -> 1 | I149: 可切 | J149: =IF(N149=$M$1,M149,IF(N149=$L$1,L149,K149)) -> TWT 20-Ku | K149: TWT 20-Ku | L149: TWT 23-Ku | M149: TWT 19-Ku | N149: P0 | O149: =F149&"-"&G149 -> RS7B-TS7B
A150: =ROW()-1 -> 149 | B150: =C150&"-["&D150&"]["&E150&"]" -> CS6D-1-2-[27][27] | C150: CS6D-1-2 | D150: 27 | E150: 27 | F150: =VLOOKUP(C150&"-I"&D150,端口信息表!B:F,5,FALSE) -> RS8B | G150: =VLOOKUP(C150&"-O"&E150,端口信息表!B:F,5,FALSE) -> TS8B | H150: =IF(I150="常通",1,VLOOKUP(B150,'开关组信息表（新）'!C:I,7,0)) -> 0 | I150: 可切 | J150: =IF(N150=$M$1,M150,IF(N150=$L$1,L150,K150)) -> TWT 21-Ku | K150: TWT 21-Ku | L150: TWT 23-Ku | M150: TWT 22-Ku | N150: P0 | O150: =F150&"-"&G150 -> RS8B-TS8B
A151: =ROW()-1 -> 150 | B151: =C151&"-["&D151&"]["&E151&"]" -> CS6D-1-2-[28][28] | C151: CS6D-1-2 | D151: 28 | E151: 28 | F151: =VLOOKUP(C151&"-I"&D151,端口信息表!B:F,5,FALSE) -> RS9B | G151: =VLOOKUP(C151&"-O"&E151,端口信息表!B:F,5,FALSE) -> TS9B | H151: =IF(I151="常通",1,VLOOKUP(B151,'开关组信息表（新）'!C:I,7,0)) -> 1 | I151: 可切 | J151: =IF(N151=$M$1,M151,IF(N151=$L$1,L151,K151)) -> TWT 22-Ku | K151: TWT 22-Ku | L151: TWT 23-Ku | M151: TWT 21-Ku | N151: P0 | O151: =F151&"-"&G151 -> RS9B-TS9B
A152: =ROW()-1 -> 151 | B152: =C152&"-["&D152&"]["&E152&"]" -> CS6D-1-2-[29][29] | C152: CS6D-1-2 | D152: 29 | E152: 29 | F152: =VLOOKUP(C152&"-I"&D152,端口信息表!B:F,5,FALSE) -> RS10B | G152: =VLOOKUP(C152&"-O"&E152,端口信息表!B:F,5,FALSE) -> TS10B | H152: =IF(I152="常通",1,VLOOKUP(B152,'开关组信息表（新）'!C:I,7,0)) -> 1 | I152: 可切 | J152: =IF(N152=$M$1,M152,IF(N152=$L$1,L152,K152)) -> TWT 24-Ku | K152: TWT 24-Ku | L152: TWT 23-Ku | M152: TWT 25-Ku | N152: P0 | O152: =F152&"-"&G152 -> RS10B-TS10B
A153: =ROW()-1 -> 152 | B153: =C153&"-["&D153&"]["&E153&"]" -> CS6D-1-2-[30][30] | C153: CS6D-1-2 | D153: 30 | E153: 30 | F153: =VLOOKUP(C153&"-I"&D153,端口信息表!B:F,5,FALSE) -> RS11B | G153: =VLOOKUP(C153&"-O"&E153,端口信息表!B:F,5,FALSE) -> TS11B | H153: =IF(I153="常通",1,VLOOKUP(B153,'开关组信息表（新）'!C:I,7,0)) -> 1 | I153: 可切 | J153: =IF(N153=$M$1,M153,IF(N153=$L$1,L153,K153)) -> TWT 25-Ku | K153: TWT 25-Ku | L153: TWT 23-Ku | M153: TWT 26-Ku | N153: P0 | O153: =F153&"-"&G153 -> RS11B-TS11B
A154: =ROW()-1 -> 153 | B154: =C154&"-["&D154&"]["&E154&"]" -> CS6D-1-2-[31][31] | C154: CS6D-1-2 | D154: 31 | E154: 31 | F154: =VLOOKUP(C154&"-I"&D154,端口信息表!B:F,5,FALSE) -> RS12B | G154: =VLOOKUP(C154&"-O"&E154,端口信息表!B:F,5,FALSE) -> TS12B | H154: =IF(I154="常通",1,VLOOKUP(B154,'开关组信息表（新）'!C:I,7,0)) -> 1 | I154: 可切 | J154: =IF(N154=$M$1,M154,IF(N154=$L$1,L154,K154)) -> TWT 26-Ku | K154: TWT 26-Ku | L154: TWT 23-Ku | M154: TWT 25-Ku | N154: P0 | O154: =F154&"-"&G154 -> RS12B-TS12B
A155: =ROW()-1 -> 154 | B155: =C155&"-["&D155&"]["&E155&"]" -> CS6E-1-1-[1][1] | C155: CS6E-1-1 | D155: 1 | E155: 1 | F155: =VLOOKUP(C155&"-I"&D155,端口信息表!B:F,5,FALSE) -> RK-HL-09-R-A | G155: =VLOOKUP(C155&"-O"&E155,端口信息表!B:F,5,FALSE) -> TS09-001-V-A | H155: =IF(I155="常通",1,VLOOKUP(B155,'开关组信息表（新）'!C:I,7,0)) -> 1 | I155: 常通 | J155: =IF(N155=$M$1,M155,IF(N155=$L$1,L155,K155)) -> 0 | N155: P0 | O155: =F155&"-"&G155 -> RK-HL-09-R-A-TS09-001-V-A
A156: =ROW()-1 -> 155 | B156: =C156&"-["&D156&"]["&E156&"]" -> CS6E-1-1-[2][2] | C156: CS6E-1-1 | D156: 2 | E156: 2 | F156: =VLOOKUP(C156&"-I"&D156,端口信息表!B:F,5,FALSE) -> RK-HL-10-R-A | G156: =VLOOKUP(C156&"-O"&E156,端口信息表!B:F,5,FALSE) -> TS10-001-V-A | H156: =IF(I156="常通",1,VLOOKUP(B156,'开关组信息表（新）'!C:I,7,0)) -> 1 | I156: 常通 | J156: =IF(N156=$M$1,M156,IF(N156=$L$1,L156,K156)) -> 0 | N156: P0 | O156: =F156&"-"&G156 -> RK-HL-10-R-A-TS10-001-V-A
A157: =ROW()-1 -> 156 | B157: =C157&"-["&D157&"]["&E157&"]" -> CS6E-1-1-[3][3] | C157: CS6E-1-1 | D157: 3 | E157: 3 | F157: =VLOOKUP(C157&"-I"&D157,端口信息表!B:F,5,FALSE) -> RK-HL-11-L-A | G157: =VLOOKUP(C157&"-O"&E157,端口信息表!B:F,5,FALSE) -> TS11-001-V-A | H157: =IF(I157="常通",1,VLOOKUP(B157,'开关组信息表（新）'!C:I,7,0)) -> 1 | I157: 常通 | J157: =IF(N157=$M$1,M157,IF(N157=$L$1,L157,K157)) -> 0 | N157: P0 | O157: =F157&"-"&G157 -> RK-HL-11-L-A-TS11-001-V-A
A158: =ROW()-1 -> 157 | B158: =C158&"-["&D158&"]["&E158&"]" -> CS6E-1-1-[4][4] | C158: CS6E-1-1 | D158: 4 | E158: 4 | F158: =VLOOKUP(C158&"-I"&D158,端口信息表!B:F,5,FALSE) -> RK-HL-12-R-A | G158: =VLOOKUP(C158&"-O"&E158,端口信息表!B:F,5,FALSE) -> TS12-001-V-A | H158: =IF(I158="常通",1,VLOOKUP(B158,'开关组信息表（新）'!C:I,7,0)) -> 1 | I158: 常通 | J158: =IF(N158=$M$1,M158,IF(N158=$L$1,L158,K158)) -> 0 | N158: P0 | O158: =F158&"-"&G158 -> RK-HL-12-R-A-TS12-001-V-A
A159: =ROW()-1 -> 158 | B159: =C159&"-["&D159&"]["&E159&"]" -> CS6E-1-1-[5][5] | C159: CS6E-1-1 | D159: 5 | E159: 5 | F159: =VLOOKUP(C159&"-I"&D159,端口信息表!B:F,5,FALSE) -> RK-HL-13-L-A | G159: =VLOOKUP(C159&"-O"&E159,端口信息表!B:F,5,FALSE) -> TS13-001-V-A | H159: =IF(I159="常通",1,VLOOKUP(B159,'开关组信息表（新）'!C:I,7,0)) -> 1 | I159: 常通 | J159: =IF(N159=$M$1,M159,IF(N159=$L$1,L159,K159)) -> 0 | N159: P0 | O159: =F159&"-"&G159 -> RK-HL-13-L-A-TS13-001-V-A
A160: =ROW()-1 -> 159 | B160: =C160&"-["&D160&"]["&E160&"]" -> CS6E-1-1-[6][6] | C160: CS6E-1-1 | D160: 6 | E160: 6 | F160: =VLOOKUP(C160&"-I"&D160,端口信息表!B:F,5,FALSE) -> RK-HL-14-L-A | G160: =VLOOKUP(C160&"-O"&E160,端口信息表!B:F,5,FALSE) -> TS14-001-V-A | H160: =IF(I160="常通",1,VLOOKUP(B160,'开关组信息表（新）'!C:I,7,0)) -> 1 | I160: 常通 | J160: =IF(N160=$M$1,M160,IF(N160=$L$1,L160,K160)) -> 0 | N160: P0 | O160: =F160&"-"&G160 -> RK-HL-14-L-A-TS14-001-V-A
A161: =ROW()-1 -> 160 | B161: =C161&"-["&D161&"]["&E161&"]" -> CS6E-1-1-[7][7] | C161: CS6E-1-1 | D161: 7 | E161: 7 | F161: =VLOOKUP(C161&"-I"&D161,端口信息表!B:F,5,FALSE) -> RK-HL-15-L-A | G161: =VLOOKUP(C161&"-O"&E161,端口信息表!B:F,5,FALSE) -> TS15-001-V-A | H161: =IF(I161="常通",1,VLOOKUP(B161,'开关组信息表（新）'!C:I,7,0)) -> 1 | I161: 常通 | J161: =IF(N161=$M$1,M161,IF(N161=$L$1,L161,K161)) -> 0 | N161: P0 | O161: =F161&"-"&G161 -> RK-HL-15-L-A-TS15-001-V-A
A162: =ROW()-1 -> 161 | B162: =C162&"-["&D162&"]["&E162&"]" -> CS6E-1-1-[8][8] | C162: CS6E-1-1 | D162: 8 | E162: 8 | F162: =VLOOKUP(C162&"-I"&D162,端口信息表!B:F,5,FALSE) -> RK-HL-17-L-A | G162: =VLOOKUP(C162&"-O"&E162,端口信息表!B:F,5,FALSE) -> TS17-001-V-A | H162: =IF(I162="常通",1,VLOOKUP(B162,'开关组信息表（新）'!C:I,7,0)) -> 1 | I162: 常通 | J162: =IF(N162=$M$1,M162,IF(N162=$L$1,L162,K162)) -> 0 | N162: P0 | O162: =F162&"-"&G162 -> RK-HL-17-L-A-TS17-001-V-A
A163: =ROW()-1 -> 162 | B163: =C163&"-["&D163&"]["&E163&"]" -> CS6E-1-1-[9][9] | C163: CS6E-1-1 | D163: 9 | E163: 9 | F163: =VLOOKUP(C163&"-I"&D163,端口信息表!B:F,5,FALSE) -> RK-HL-18-L-A | G163: =VLOOKUP(C163&"-O"&E163,端口信息表!B:F,5,FALSE) -> TS18-001-V-A | H163: =IF(I163="常通",1,VLOOKUP(B163,'开关组信息表（新）'!C:I,7,0)) -> 1 | I163: 常通 | J163: =IF(N163=$M$1,M163,IF(N163=$L$1,L163,K163)) -> 0 | N163: P0 | O163: =F163&"-"&G163 -> RK-HL-18-L-A-TS18-001-V-A
A164: =ROW()-1 -> 163 | B164: =C164&"-["&D164&"]["&E164&"]" -> CS6E-1-1-[10][10] | C164: CS6E-1-1 | D164: 10 | E164: 10 | F164: =VLOOKUP(C164&"-I"&D164,端口信息表!B:F,5,FALSE) -> RK-HL-19-L-A | G164: =VLOOKUP(C164&"-O"&E164,端口信息表!B:F,5,FALSE) -> TS19-001-V-A | H164: =IF(I164="常通",1,VLOOKUP(B164,'开关组信息表（新）'!C:I,7,0)) -> 1 | I164: 常通 | J164: =IF(N164=$M$1,M164,IF(N164=$L$1,L164,K164)) -> 0 | N164: P0 | O164: =F164&"-"&G164 -> RK-HL-19-L-A-TS19-001-V-A
A165: =ROW()-1 -> 164 | B165: =C165&"-["&D165&"]["&E165&"]" -> CS6E-1-1-[11][11] | C165: CS6E-1-1 | D165: 11 | E165: 11 | F165: =VLOOKUP(C165&"-I"&D165,端口信息表!B:F,5,FALSE) -> RK-HL-20-R-A | G165: =VLOOKUP(C165&"-O"&E165,端口信息表!B:F,5,FALSE) -> TS20-001-V-A | H165: =IF(I165="常通",1,VLOOKUP(B165,'开关组信息表（新）'!C:I,7,0)) -> 1 | I165: 常通 | J165: =IF(N165=$M$1,M165,IF(N165=$L$1,L165,K165)) -> 0 | N165: P0 | O165: =F165&"-"&G165 -> RK-HL-20-R-A-TS20-001-V-A
A166: =ROW()-1 -> 165 | B166: =C166&"-["&D166&"]["&E166&"]" -> CS6E-1-1-[12][12] | C166: CS6E-1-1 | D166: 12 | E166: 12 | F166: =VLOOKUP(C166&"-I"&D166,端口信息表!B:F,5,FALSE) -> RK-HL-21-R-A | G166: =VLOOKUP(C166&"-O"&E166,端口信息表!B:F,5,FALSE) -> TS21-001-V-A | H166: =IF(I166="常通",1,VLOOKUP(B166,'开关组信息表（新）'!C:I,7,0)) -> 1 | I166: 常通 | J166: =IF(N166=$M$1,M166,IF(N166=$L$1,L166,K166)) -> 0 | N166: P0 | O166: =F166&"-"&G166 -> RK-HL-21-R-A-TS21-001-V-A
A167: =ROW()-1 -> 166 | B167: =C167&"-["&D167&"]["&E167&"]" -> CS6E-1-1-[13][13] | C167: CS6E-1-1 | D167: 13 | E167: 13 | F167: =VLOOKUP(C167&"-I"&D167,端口信息表!B:F,5,FALSE) -> RK-HL-22-L-A | G167: =VLOOKUP(C167&"-O"&E167,端口信息表!B:F,5,FALSE) -> TS22-001-V-A | H167: =IF(I167="常通",1,VLOOKUP(B167,'开关组信息表（新）'!C:I,7,0)) -> 1 | I167: 常通 | J167: =IF(N167=$M$1,M167,IF(N167=$L$1,L167,K167)) -> 0 | N167: P0 | O167: =F167&"-"&G167 -> RK-HL-22-L-A-TS22-001-V-A
...

Sheet 频率块划分实时状态
A1: ID | B1: 频率块代码 | C1: 频率块代码-2 | D1: 维护备注-履约状态 | E1: 维护备注-用户 | F1: 维护备注-销售 | G1: 开关代码 | H1: 索引“开关状态” | I1: 偏移量 | J1: 占用宽度 | K1: 状态（划分P/回收R/无效N） | L1: 状态修改时间 | M1: 用途分类（出租/合作/自用/禁用） | N1: 上行起频率 | O1: 上行止频率 | P1: 下行起频率 | Q1: 下行止频率 | R1: 索引“卫星” | S1: 索引“入端口通道” | T1: 索引“出端口通道” | U1: 索引“开关通道宽度” | V1: 索引“入通道起频率” | W1: 索引“入通道止频率” | X1: 索引“出通道起频率” | Y1: 索引“出通道止频率”
A2: =ROW()-1 -> 1 | B2: =G2&"-"&"OFF"&I2&"-BW"&J2 -> CS10R-1-1-[1][1]-OFF-1-BW32 | C2: =R2&"_BW"&TEXT(O2-N2,"000.00")&"_U"&VLOOKUP(R2&"-"&S2,通道清单!C:L,5,FALSE)&LEFT("_____",5-LEN(VLOOKUP(R2&"-"&S2,通道清单!C:L,4,FALSE)))&VLOOKUP(R2&"-"&S2,通道清单!C:L,4,FALSE)&"_S"&TEXT(N2,"00000.00")&"_E"&TEXT(O2,"00000.00")&"_D"&VLOOKUP(R2&"-"&T2,通道清单!C:L,5,FALSE)&LEFT("_____",5-LEN(VLOOKUP(R2&"-"&T2,通道清单!C:L,4,FALSE)))&VLOOKUP(R2&"-"&T2,通道清单!C:L,4,FALSE)&"_S"&TEXT(P2,"00000.00")&"_E"&TEXT(Q2,"00000.00") -> CS10R_BW032.00_UH____C_S14007.00_E14039.00_DV____C_S12257.00_E12289.00 | G2: CS10R-1-1-[1][1] | H2: =VLOOKUP(G2,开关状态表!B:I,7,FALSE) -> 1 | I2: -1 | J2: 32 | K2: P | M2: 出租 | N2: =V2+I2 -> 14007 | O2: =N2+J2 -> 14039 | P2: =X2+I2 -> 12257 | Q2: =P2+J2 -> 12289 | R2: =VLOOKUP(VLOOKUP(G2,开关状态表!B:H,2,FALSE),矩阵信息表!B:H,2,FALSE) -> CS10R | S2: =VLOOKUP(G2,开关状态表!B:H,5,FALSE) -> RC1A | T2: =VLOOKUP(G2,开关状态表!B:H,6,FALSE) -> TC1A | U2: =VLOOKUP(R2&"-"&S2,通道清单!C:L,8,FALSE) -> 30 | V2: =VLOOKUP(R2&"-"&S2,通道清单!C:L,9,FALSE) -> 14008 | W2: =VLOOKUP(R2&"-"&S2,通道清单!C:L,10,FALSE) -> 14038 | X2: =VLOOKUP(R2&"-"&T2,通道清单!C:L,9,FALSE) -> 12258 | Y2: =VLOOKUP(R2&"-"&T2,通道清单!C:L,10,FALSE) -> 12288
A3: =ROW()-1 -> 2 | B3: =G3&"-"&"OFF"&I3&"-BW"&J3 -> CS10R-1-1-[2][2]-OFF-2.5-BW2.5 | C3: =R3&"_BW"&TEXT(O3-N3,"000.00")&"_U"&VLOOKUP(R3&"-"&S3,通道清单!C:L,5,FALSE)&LEFT("_____",5-LEN(VLOOKUP(R3&"-"&S3,通道清单!C:L,4,FALSE)))&VLOOKUP(R3&"-"&S3,通道清单!C:L,4,FALSE)&"_S"&TEXT(N3,"00000.00")&"_E"&TEXT(O3,"00000.00")&"_D"&VLOOKUP(R3&"-"&T3,通道清单!C:L,5,FALSE)&LEFT("_____",5-LEN(VLOOKUP(R3&"-"&T3,通道清单!C:L,4,FALSE)))&VLOOKUP(R3&"-"&T3,通道清单!C:L,4,FALSE)&"_S"&TEXT(P3,"00000.00")&"_E"&TEXT(Q3,"00000.00") -> CS10R_BW002.50_UH____C_S14040.50_E14043.00_DV____C_S12290.50_E12293.00 | G3: CS10R-1-1-[2][2] | H3: =VLOOKUP(G3,开关状态表!B:I,7,FALSE) -> 1 | I3: -2.5 | J3: 2.5 | K3: P | M3: 出租 | N3: =V3+I3 -> 14040.5 | O3: =N3+J3 -> 14043 | P3: =X3+I3 -> 12290.5 | Q3: =P3+J3 -> 12293 | R3: =VLOOKUP(VLOOKUP(G3,开关状态表!B:H,2,FALSE),矩阵信息表!B:H,2,FALSE) -> CS10R | S3: =VLOOKUP(G3,开关状态表!B:H,5,FALSE) -> RC2A | T3: =VLOOKUP(G3,开关状态表!B:H,6,FALSE) -> TC2A | U3: =VLOOKUP(R3&"-"&S3,通道清单!C:L,8,FALSE) -> 54 | V3: =VLOOKUP(R3&"-"&S3,通道清单!C:L,9,FALSE) -> 14043 | W3: =VLOOKUP(R3&"-"&S3,通道清单!C:L,10,FALSE) -> 14097 | X3: =VLOOKUP(R3&"-"&T3,通道清单!C:L,9,FALSE) -> 12293 | Y3: =VLOOKUP(R3&"-"&T3,通道清单!C:L,10,FALSE) -> 12347
A4: =ROW()-1 -> 3 | B4: =G4&"-"&"OFF"&I4&"-BW"&J4 -> CS10R-1-1-[2][2]-OFF0-BW9 | C4: =R4&"_BW"&TEXT(O4-N4,"000.00")&"_U"&VLOOKUP(R4&"-"&S4,通道清单!C:L,5,FALSE)&LEFT("_____",5-LEN(VLOOKUP(R4&"-"&S4,通道清单!C:L,4,FALSE)))&VLOOKUP(R4&"-"&S4,通道清单!C:L,4,FALSE)&"_S"&TEXT(N4,"00000.00")&"_E"&TEXT(O4,"00000.00")&"_D"&VLOOKUP(R4&"-"&T4,通道清单!C:L,5,FALSE)&LEFT("_____",5-LEN(VLOOKUP(R4&"-"&T4,通道清单!C:L,4,FALSE)))&VLOOKUP(R4&"-"&T4,通道清单!C:L,4,FALSE)&"_S"&TEXT(P4,"00000.00")&"_E"&TEXT(Q4,"00000.00") -> CS10R_BW009.00_UH____C_S14043.00_E14052.00_DV____C_S12293.00_E12302.00 | G4: CS10R-1-1-[2][2] | H4: =VLOOKUP(G4,开关状态表!B:I,7,FALSE) -> 1 | I4: 0 | J4: 9 | K4: P | M4: 出租 | N4: =V4+I4 -> 14043 | O4: =N4+J4 -> 14052 | P4: =X4+I4 -> 12293 | Q4: =P4+J4 -> 12302 | R4: =VLOOKUP(VLOOKUP(G4,开关状态表!B:H,2,FALSE),矩阵信息表!B:H,2,FALSE) -> CS10R | S4: =VLOOKUP(G4,开关状态表!B:H,5,FALSE) -> RC2A | T4: =VLOOKUP(G4,开关状态表!B:H,6,FALSE) -> TC2A | U4: =VLOOKUP(R4&"-"&S4,通道清单!C:L,8,FALSE) -> 54 | V4: =VLOOKUP(R4&"-"&S4,通道清单!C:L,9,FALSE) -> 14043 | W4: =VLOOKUP(R4&"-"&S4,通道清单!C:L,10,FALSE) -> 14097 | X4: =VLOOKUP(R4&"-"&T4,通道清单!C:L,9,FALSE) -> 12293 | Y4: =VLOOKUP(R4&"-"&T4,通道清单!C:L,10,FALSE) -> 12347
A5: =ROW()-1 -> 4 | B5: =G5&"-"&"OFF"&I5&"-BW"&J5 -> CS10R-1-1-[2][2]-OFF9-BW36 | C5: =R5&"_BW"&TEXT(O5-N5,"000.00")&"_U"&VLOOKUP(R5&"-"&S5,通道清单!C:L,5,FALSE)&LEFT("_____",5-LEN(VLOOKUP(R5&"-"&S5,通道清单!C:L,4,FALSE)))&VLOOKUP(R5&"-"&S5,通道清单!C:L,4,FALSE)&"_S"&TEXT(N5,"00000.00")&"_E"&TEXT(O5,"00000.00")&"_D"&VLOOKUP(R5&"-"&T5,通道清单!C:L,5,FALSE)&LEFT("_____",5-LEN(VLOOKUP(R5&"-"&T5,通道清单!C:L,4,FALSE)))&VLOOKUP(R5&"-"&T5,通道清单!C:L,4,FALSE)&"_S"&TEXT(P5,"00000.00")&"_E"&TEXT(Q5,"00000.00") -> CS10R_BW036.00_UH____C_S14052.00_E14088.00_DV____C_S12302.00_E12338.00 | G5: CS10R-1-1-[2][2] | H5: =VLOOKUP(G5,开关状态表!B:I,7,FALSE) -> 1 | I5: 9 | J5: 36 | K5: P | M5: 出租 | N5: =V5+I5 -> 14052 | O5: =N5+J5 -> 14088 | P5: =X5+I5 -> 12302 | Q5: =P5+J5 -> 12338 | R5: =VLOOKUP(VLOOKUP(G5,开关状态表!B:H,2,FALSE),矩阵信息表!B:H,2,FALSE) -> CS10R | S5: =VLOOKUP(G5,开关状态表!B:H,5,FALSE) -> RC2A | T5: =VLOOKUP(G5,开关状态表!B:H,6,FALSE) -> TC2A | U5: =VLOOKUP(R5&"-"&S5,通道清单!C:L,8,FALSE) -> 54 | V5: =VLOOKUP(R5&"-"&S5,通道清单!C:L,9,FALSE) -> 14043 | W5: =VLOOKUP(R5&"-"&S5,通道清单!C:L,10,FALSE) -> 14097 | X5: =VLOOKUP(R5&"-"&T5,通道清单!C:L,9,FALSE) -> 12293 | Y5: =VLOOKUP(R5&"-"&T5,通道清单!C:L,10,FALSE) -> 12347
A6: =ROW()-1 -> 5 | B6: =G6&"-"&"OFF"&I6&"-BW"&J6 -> CS10R-1-1-[2][2]-OFF45-BW2 | C6: =R6&"_BW"&TEXT(O6-N6,"000.00")&"_U"&VLOOKUP(R6&"-"&S6,通道清单!C:L,5,FALSE)&LEFT("_____",5-LEN(VLOOKUP(R6&"-"&S6,通道清单!C:L,4,FALSE)))&VLOOKUP(R6&"-"&S6,通道清单!C:L,4,FALSE)&"_S"&TEXT(N6,"00000.00")&"_E"&TEXT(O6,"00000.00")&"_D"&VLOOKUP(R6&"-"&T6,通道清单!C:L,5,FALSE)&LEFT("_____",5-LEN(VLOOKUP(R6&"-"&T6,通道清单!C:L,4,FALSE)))&VLOOKUP(R6&"-"&T6,通道清单!C:L,4,FALSE)&"_S"&TEXT(P6,"00000.00")&"_E"&TEXT(Q6,"00000.00") -> CS10R_BW002.00_UH____C_S14088.00_E14090.00_DV____C_S12338.00_E12340.00 | G6: CS10R-1-1-[2][2] | H6: =VLOOKUP(G6,开关状态表!B:I,7,FALSE) -> 1 | I6: 45 | J6: 2 | K6: P | M6: 出租 | N6: =V6+I6 -> 14088 | O6: =N6+J6 -> 14090 | P6: =X6+I6 -> 12338 | Q6: =P6+J6 -> 12340 | R6: =VLOOKUP(VLOOKUP(G6,开关状态表!B:H,2,FALSE),矩阵信息表!B:H,2,FALSE) -> CS10R | S6: =VLOOKUP(G6,开关状态表!B:H,5,FALSE) -> RC2A | T6: =VLOOKUP(G6,开关状态表!B:H,6,FALSE) -> TC2A | U6: =VLOOKUP(R6&"-"&S6,通道清单!C:L,8,FALSE) -> 54 | V6: =VLOOKUP(R6&"-"&S6,通道清单!C:L,9,FALSE) -> 14043 | W6: =VLOOKUP(R6&"-"&S6,通道清单!C:L,10,FALSE) -> 14097 | X6: =VLOOKUP(R6&"-"&T6,通道清单!C:L,9,FALSE) -> 12293 | Y6: =VLOOKUP(R6&"-"&T6,通道清单!C:L,10,FALSE) -> 12347
A7: =ROW()-1 -> 6 | B7: CS10R-1-1-[2][2]-OFF45-BW2.5 | C7: =R7&"_BW"&TEXT(O7-N7,"000.00")&"_U"&VLOOKUP(R7&"-"&S7,通道清单!C:L,5,FALSE)&LEFT("_____",5-LEN(VLOOKUP(R7&"-"&S7,通道清单!C:L,4,FALSE)))&VLOOKUP(R7&"-"&S7,通道清单!C:L,4,FALSE)&"_S"&TEXT(N7,"00000.00")&"_E"&TEXT(O7,"00000.00")&"_D"&VLOOKUP(R7&"-"&T7,通道清单!C:L,5,FALSE)&LEFT("_____",5-LEN(VLOOKUP(R7&"-"&T7,通道清单!C:L,4,FALSE)))&VLOOKUP(R7&"-"&T7,通道清单!C:L,4,FALSE)&"_S"&TEXT(P7,"00000.00")&"_E"&TEXT(Q7,"00000.00") -> CS10R_BW000.50_UH____C_S14090.00_E14090.50_DV____C_S12340.00_E12340.50 | G7: CS10R-1-1-[2][2] | H7: 1 | I7: 47 | J7: 0.5 | K7: P | M7: 出租 | N7: =V7+I7 -> 14090 | O7: =N7+J7 -> 14090.5 | P7: =X7+I7 -> 12340 | Q7: =P7+J7 -> 12340.5 | R7: =VLOOKUP(VLOOKUP(G7,开关状态表!B:H,2,FALSE),矩阵信息表!B:H,2,FALSE) -> CS10R | S7: =VLOOKUP(G7,开关状态表!B:H,5,FALSE) -> RC2A | T7: =VLOOKUP(G7,开关状态表!B:H,6,FALSE) -> TC2A | U7: =VLOOKUP(R7&"-"&S7,通道清单!C:L,8,FALSE) -> 54 | V7: =VLOOKUP(R7&"-"&S7,通道清单!C:L,9,FALSE) -> 14043 | W7: =VLOOKUP(R7&"-"&S7,通道清单!C:L,10,FALSE) -> 14097 | X7: =VLOOKUP(R7&"-"&T7,通道清单!C:L,9,FALSE) -> 12293 | Y7: =VLOOKUP(R7&"-"&T7,通道清单!C:L,10,FALSE) -> 12347
